Workbook

Sheet TRENUTNA ZALOGA
A1: Šifra materiala | B1: Naziv materiala | C1: Širina | D1: Višina | E1: Gramatura | F1: Začetna zaloga | G1: Prispelo | H1: Odpis | I1: TRENUTNA ZALOGA
A2: 112 | B2: Claro silk | C2: 100 | D2: 70 | E2: 90 | F2: 400 | G2: =SUMIF(PRISPELO!B:B, A2, PRISPELO!G:G) | H2: =SUMIF(ODPIS!B:B, A2, ODPIS!G:G) | I2: =F2 + G2 - H2
A3: 114 | B3: Claro silk | C3: 90 | D3: 64 | E3: 90 | F3: 0 | G3: =SUMIF(PRISPELO!B:B, A3, PRISPELO!G:G) | H3: =SUMIF(ODPIS!B:B, A3, ODPIS!G:G) | I3: =F3 + G3 - H3
A4: 117 | B4: Claro silk | C4: 64 | D4: 90 | E4: 90 | F4: 0 | G4: =SUMIF(PRISPELO!B:B, A4, PRISPELO!G:G) | H4: =SUMIF(ODPIS!B:B, A4, ODPIS!G:G) | I4: =F4 + G4 - H4
A5: 118 | B5: Claro silk | C5: 70 | D5: 100 | E5: 90 | F5: 0 | G5: =SUMIF(PRISPELO!B:B, A5, PRISPELO!G:G) | H5: =SUMIF(ODPIS!B:B, A5, ODPIS!G:G) | I5: =F5 + G5 - H5
A6: 119 | B6: Claro silk | C6: 70 | D6: 100 | E6: 115 | F6: 0 | G6: =SUMIF(PRISPELO!B:B, A6, PRISPELO!G:G) | H6: =SUMIF(ODPIS!B:B, A6, ODPIS!G:G) | I6: =F6 + G6 - H6
A7: 125 | B7: Claro silk | C7: 100 | D7: 70 | E7: 100 | F7: 0 | G7: =SUMIF(PRISPELO!B:B, A7, PRISPELO!G:G) | H7: =SUMIF(ODPIS!B:B, A7, ODPIS!G:G) | I7: =F7 + G7 - H7
A8: 128 | B8: Claro silk | C8: 90 | D8: 64 | E8: 100 | F8: 0 | G8: =SUMIF(PRISPELO!B:B, A8, PRISPELO!G:G) | H8: =SUMIF(ODPIS!B:B, A8, ODPIS!G:G) | I8: =F8 + G8 - H8
A9: 135 | B9: Claro silk | C9: 64 | D9: 90 | E9: 100 | F9: 0 | G9: =SUMIF(PRISPELO!B:B, A9, PRISPELO!G:G) | H9: =SUMIF(ODPIS!B:B, A9, ODPIS!G:G) | I9: =F9 + G9 - H9
A10: 138 | B10: Claro silk | C10: 90 | D10: 64 | E10: 115 | F10: 0 | G10: =SUMIF(PRISPELO!B:B, A10, PRISPELO!G:G) | H10: =SUMIF(ODPIS!B:B, A10, ODPIS!G:G) | I10: =F10 + G10 - H10
A11: 139 | B11: Claro silk | C11: 64 | D11: 90 | E11: 115 | F11: 0 | G11: =SUMIF(PRISPELO!B:B, A11, PRISPELO!G:G) | H11: =SUMIF(ODPIS!B:B, A11, ODPIS!G:G) | I11: =F11 + G11 - H11
A12: 145 | B12: Claro silk | C12: 100 | D12: 70 | E12: 115 | F12: 0 | G12: =SUMIF(PRISPELO!B:B, A12, PRISPELO!G:G) | H12: =SUMIF(ODPIS!B:B, A12, ODPIS!G:G) | I12: =F12 + G12 - H12
A13: 149 | B13: Claro silk | C13: 90 | D13: 64 | E13: 135 | F13: 0 | G13: =SUMIF(PRISPELO!B:B, A13, PRISPELO!G:G) | H13: =SUMIF(ODPIS!B:B, A13, ODPIS!G:G) | I13: =F13 + G13 - H13
... A2254: 4316 | B2254: MAGNO SATIN | C2254: 72 | D2254: 102 | E2254: 300 | F2254: 0 | G2254: =SUMIF(PRISPELO!B:B, A2254, PRISPELO!G:G) | H2254: =SUMIF(ODPIS!B:B, A2254, ODPIS!G:G) | I2254: =F2254 + G2254 - H2254
A2255: 4317 | B2255: MULTICOLOR MARIBEL | C2255: 70 | D2255: 100 | E2255: 400 | F2255: 0 | G2255: =SUMIF(PRISPELO!B:B, A2255, PRISPELO!G:G) | H2255: =SUMIF(ODPIS!B:B, A2255, ODPIS!G:G) | I2255: 250
A2256: 4318 | B2256: AMBER OFFSET | C2256: 90 | D2256: 64 | E2256: 140 | F2256: 0 | G2256: =SUMIF(PRISPELO!B:B, A2256, PRISPELO!G:G) | H2256: =SUMIF(ODPIS!B:B, A2256, ODPIS!G:G) | I2256: =F2256 + G2256 - H2256
A2257: 4319 | B2257: VELUM 70 EP KR | C2257: 100 | D2257: 70 | E2257: 125 | F2257: 0 | G2257: =SUMIF(PRISPELO!B:B, A2257, PRISPELO!G:G) | H2257: =SUMIF(ODPIS!B:B, A2257, ODPIS!G:G) | I2257: 50
A2258: 4320 | B2258: CHROMOSTAR | C2258: 102 | D2258: 72 | E2258: 350 | F2258: 0 | G2258: =SUMIF(PRISPELO!B:B, A2258, PRISPELO!G:G) | H2258: =SUMIF(ODPIS!B:B, A2258, ODPIS!G:G) | I2258: 350
A2259: 4321 | B2259: ROYAL CCOAT PREMIUM GLOSS | C2259: 70 | D2259: 100 | E2259: 150 | F2259: 0 | G2259: =SUMIF(PRISPELO!B:B, A2259, PRISPELO!G:G) | H2259: =SUMIF(ODPIS!B:B, A2259, ODPIS!G:G) | I2259: =F2259 + G2259 - H2259
A2260: 4322 | B2260: EAGLE PLUS | C2260: 69.8 | D2260: 42.2 | E2260: 270 | F2260: 0 | G2260: =SUMIF(PRISPELO!B:B, A2260, PRISPELO!G:G) | H2260: =SUMIF(ODPIS!B:B, A2260, ODPIS!G:G) | I2260: =F2260 + G2260 - H2260
A2261: 4323 | B2261: BOARDONE HIBULK GC1 | C2261: 102 | D2261: 72 | E2261: 270 | F2261: 0 | G2261: =SUMIF(PRISPELO!B:B, A2261, PRISPELO!G:G) | H2261: =SUMIF(ODPIS!B:B, A2261, ODPIS!G:G) | I2261: 390
A2262: 4324 | B2262: GARDA BOOK WHITE | C2262: 64 | D2262: 90 | E2262: 80 | F2262: 0 | G2262: =SUMIF(PRISPELO!B:B, A2262, PRISPELO!G:G) | H2262: =SUMIF(ODPIS!B:B, A2262, ODPIS!G:G) | I2262: 4500
A2263: 4325 | B2263: MULTICOLOR MARIBEL | C2263: 70 | D2263: 100 | E2263: 250 | F2263: 0 | G2263: =SUMIF(PRISPELO!B:B, A2263, PRISPELO!G:G) | H2263: =SUMIF(ODPIS!B:B, A2263, ODPIS!G:G) | I2263: 3000
A2264: 4326 | B2264: COATED | C2264: 72 | D2264: 102 | E2264: 250 | F2264: 0 | G2264: =SUMIF(PRISPELO!B:B, A2264, PRISPELO!G:G) | H2264: =SUMIF(ODPIS!B:B, A2264, ODPIS!G:G) | I2264: =F2264 + G2264 - H2264
A2265: 3005 | B2265: IQ color zelen MA42 | C2265: 42 | D2265: 29.7 | E2265: 80 | F2265: 0 | G2265: =SUMIF(PRISPELO!B:B, A2265, PRISPELO!G:G) | H2265: =SUMIF(ODPIS!B:B, A2265, ODPIS!G:G) | I2265: =F2265 + G2265 - H2265
A2266: 4327 | B2266: GRAFOPAK | C2266: 72 | D2266: 102 | E2266: 250 | F2266: 0 | G2266: =SUMIF(PRISPELO!B:B, A2266, PRISPELO!G:G) | H2266: =SUMIF(ODPIS!B:B, A2266, ODPIS!G:G) | I2266: =F2266 + G2266 - H2266
A2267: 4328 | B2267: FORMULA CFB | C2267: 45 | D2267: 64 | E2267: 60 | F2267: 0 | G2267: =SUMIF(PRISPELO!B:B, A2267, PRISPELO!G:G) | H2267: =SUMIF(ODPIS!B:B, A2267, ODPIS!G:G) | I2267: 250
A2268: 4329 | B2268: FORMULA CFB GREEN | C2268: 45 | D2268: 64 | E2268: 60 | F2268: 0 | G2268: =SUMIF(PRISPELO!B:B, A2268, PRISPELO!G:G) | H2268: =SUMIF(ODPIS!B:B, A2268, ODPIS!G:G) | I2268: =F2268 + G2268 - H2268
A2269: 4330 | B2269: BELI NATRON | C2269: 70.5 | D2269: 101 | E2269: 120 | F2269: 0 | G2269: =SUMIF(PRISPELO!B:B, A2269, PRISPELO!G:G) | H2269: =SUMIF(ODPIS!B:B, A2269, ODPIS!G:G) | I2269: 150
A2270: 4331 | B2270: ALGRO DESIGN | C2270: 72 | D2270: 102 | E2270: 240 | F2270: 0 | G2270: =SUMIF(PRISPELO!B:B, A2270, PRISPELO!G:G) | H2270: =SUMIF(ODPIS!B:B, A2270, ODPIS!G:G) | I2270: =F2270 + G2270 - H2270
A2271: 4078 | B2271: TERRAPRINT GLOSS | C2271: 0 | D2271: 0 | E2271: 0 | F2271: 0 | G2271: =SUMIF(PRISPELO!B:B, A2271, PRISPELO!G:G) | H2271: =SUMIF(ODPIS!B:B, A2271, ODPIS!G:G) | I2271: =F2271 + G2271 - H2271
A2272: 4079 | B2272: TERRAPRINT GLOSS | C2272: 0 | D2272: 0 | E2272: 0 | F2272: 0 | G2272: =SUMIF(PRISPELO!B:B, A2272, PRISPELO!G:G) | H2272: =SUMIF(ODPIS!B:B, A2272, ODPIS!G:G) | I2272: =F2272 + G2272 - H2272
A2273: 4111 | B2273: MAYSPIES POWERTACK | C2273: 0 | D2273: 0 | E2273: 0 | F2273: 0 | G2273: =SUMIF(PRISPELO!B:B, A2273, PRISPELO!G:G) | H2273: =SUMIF(ODPIS!B:B, A2273, ODPIS!G:G) | I2273: =F2273 + G2273 - H2273
A2274: 4332 | B2274: GARDA PAT 1.1 | C2274: 90 | D2274: 64 | E2274: 170 | F2274: 0 | G2274: =SUMIF(PRISPELO!B:B, A2274, PRISPELO!G:G) | H2274: =SUMIF(ODPIS!B:B, A2274, ODPIS!G:G) | I2274: =F2274 + G2274 - H2274
A2275: 4333 | B2275: BOARDONE HIBULK GC1 | C2275: 102 | D2275: 72 | E2275: 235 | F2275: 800 | G2275: =SUMIF(PRISPELO!B:B, A2275, PRISPELO!G:G) | H2275: =SUMIF(ODPIS!B:B, A2275, ODPIS!G:G) | I2275: =F2275 + G2275 - H2275
A2276: 4335 | B2276: NIVIS NEXT GLOSS | C2276: 72 | D2276: 102 | E2276: 250 | F2276: 180 | G2276: =SUMIF(PRISPELO!B:B, A2276, PRISPELO!G:G) | H2276: =SUMIF(ODPIS!B:B, A2276, ODPIS!G:G) | I2276: =F2276 + G2276 - H2276
A2277: 4336 | B2277: Dns preformens plus | C2277: 45 | D2277: 64 | E2277: 90 | F2277: 520 | G2277: =SUMIF(PRISPELO!B:B, A2277, PRISPELO!G:G) | H2277: =SUMIF(ODPIS!B:B, A2277, ODPIS!G:G) | I2277: =F2277 + G2277 - H2277
A2278: 4337 | B2278: Boardone hibulk GC1 | C2278: 102 | D2278: 72 | E2278: 325 | F2278: 1000 | G2278: =SUMIF(PRISPELO!B:B, A2278, PRISPELO!G:G) | H2278: =SUMIF(ODPIS!B:B, A2278, ODPIS!G:G) | I2278: =F2278 + G2278 - H2278
A2279: 4338 | B2279: Garda matt eleven | C2279: 92 | D2279: 65 | E2279: 170 | G2279: =SUMIF(PRISPELO!B:B, A2279, PRISPELO!G:G) | H2279: =SUMIF(ODPIS!B:B, A2279, ODPIS!G:G) | I2279: =F2279 + G2279 - H2279
A2280: 4339 | B2280: Condat matt perigord | C2280: 100 | D2280: 70 | E2280: 170 | F2280: 300 | G2280: =SUMIF(PRISPELO!B:B, A2280, PRISPELO!G:G) | H2280: =SUMIF(ODPIS!B:B, A2280, ODPIS!G:G) | I2280: =F2280 + G2280 - H2280
...

Sheet PRISPELO
A1: Datum | B1: Šifra materiala | C1: Naziv (Avtomatsko) | D1: Širina | E1: Višina | F1: Gramatura | G1: Količina (Prejem) | H1: Št. Dobavnice | I1: Dobavitelj | J1: Opomba
A2: 46253 | B2: 2295 | C2: =IF(B2="","",VLOOKUP(B2,'TRENUTNA ZALOGA'!A:B,2,FALSE)) | D2: =IF(B2="","",VLOOKUP(B2,'TRENUTNA ZALOGA'!A:C,3,FALSE)) | E2: =IF(B2="","",VLOOKUP(B2,'TRENUTNA ZALOGA'!A:D,4,FALSE)) | F2: =IF(B2="","",VLOOKUP(B2,'TRENUTNA ZALOGA'!A:E,5,FALSE)) | G2: 2000 | H2: 2041027777/18.08.2026 | I2: EUROPAPIR D.O.O
A3: 46253 | B3: 2434 | C3: =IF(B3="","",VLOOKUP(B3,'TRENUTNA ZALOGA'!A:B,2,FALSE)) | D3: =IF(B3="","",VLOOKUP(B3,'TRENUTNA ZALOGA'!A:C,3,FALSE)) | E3: =IF(B3="","",VLOOKUP(B3,'TRENUTNA ZALOGA'!A:D,4,FALSE)) | F3: =IF(B3="","",VLOOKUP(B3,'TRENUTNA ZALOGA'!A:E,5,FALSE)) | G3: 2000 | H3: 2041027811/18.08.2026 | I3: EUROPAPIR D.O.O
A4: 46254 | B4: 1684 | C4: =IF(B4="","",VLOOKUP(B4,'TRENUTNA ZALOGA'!A:B,2,FALSE)) | D4: =IF(B4="","",VLOOKUP(B4,'TRENUTNA ZALOGA'!A:C,3,FALSE)) | E4: =IF(B4="","",VLOOKUP(B4,'TRENUTNA ZALOGA'!A:D,4,FALSE)) | F4: =IF(B4="","",VLOOKUP(B4,'TRENUTNA ZALOGA'!A:E,5,FALSE)) | G4: 2500 | I4: Stafix ltd
C5: =IF(B5="","",VLOOKUP(B5,'TRENUTNA ZALOGA'!A:B,2,FALSE))
C6: =IF(B6="","",VLOOKUP(B6,'TRENUTNA ZALOGA'!A:B,2,FALSE))
C7: =IF(B7="","",VLOOKUP(B7,'TRENUTNA ZALOGA'!A:B,2,FALSE))
C8: =IF(B8="","",VLOOKUP(B8,'TRENUTNA ZALOGA'!A:B,2,FALSE))
C9: =IF(B9="","",VLOOKUP(B9,'TRENUTNA ZALOGA'!A:B,2,FALSE))
C10: =IF(B10="","",VLOOKUP(B10,'TRENUTNA ZALOGA'!A:B,2,FALSE))
C11: =IF(B11="","",VLOOKUP(B11,'TRENUTNA ZALOGA'!A:B,2,FALSE))
C12: =IF(B12="","",VLOOKUP(B12,'TRENUTNA ZALOGA'!A:B,2,FALSE))
C13: =IF(B13="","",VLOOKUP(B13,'TRENUTNA ZALOGA'!A:B,2,FALSE))
C14: =IF(B14="","",VLOOKUP(B14,'TRENUTNA ZALOGA'!A:B,2,FALSE))
C15: =IF(B15="","",VLOOKUP(B15,'TRENUTNA ZALOGA'!A:B,2,FALSE))
C16: =IF(B16="","",VLOOKUP(B16,'TRENUTNA ZALOGA'!A:B,2,FALSE))
... C1908: =IF(B1908="","",VLOOKUP(B1908,'TRENUTNA ZALOGA'!A:B,2,FALSE))

Sheet ODPIS
A1: Datum | B1: Šifra materiala | C1: Naziv (Avtomatsko) | D1: Širina | E1: Višina | F1: Gramatura | G1: Količina (Odpis) | H1: Delovni Nalog | I1: Oseba | J1: Opomba
A2: 46254 | B2: 4288 | C2: =IF(B2="","",VLOOKUP(B2,'TRENUTNA ZALOGA'!A:B,2,FALSE)) | D2: =IF(B2="","",VLOOKUP(B2,'TRENUTNA ZALOGA'!A:C,3,FALSE)) | E2: =IF(B2="","",VLOOKUP(B2,'TRENUTNA ZALOGA'!A:D,4,FALSE)) | F2: =IF(B2="","",VLOOKUP(B2,'TRENUTNA ZALOGA'!A:E,5,FALSE)) | G2: 650 | H2: 1195/26 | I2: Simon | J2: VENDO
A3: 46254 | B3: 1136 | C3: =IF(B3="","",VLOOKUP(B3,'TRENUTNA ZALOGA'!A:B,2,FALSE)) | D3: =IF(B3="","",VLOOKUP(B3,'TRENUTNA ZALOGA'!A:C,3,FALSE)) | E3: =IF(B3="","",VLOOKUP(B3,'TRENUTNA ZALOGA'!A:D,4,FALSE)) | F3: =IF(B3="","",VLOOKUP(B3,'TRENUTNA ZALOGA'!A:E,5,FALSE)) | G3: 200 | H3: 1202/26 | I3: Simon | J3: Voda Rogla
A4: 46254 | B4: 1136 | C4: =IF(B4="","",VLOOKUP(B4,'TRENUTNA ZALOGA'!A:B,2,FALSE)) | D4: =IF(B4="","",VLOOKUP(B4,'TRENUTNA ZALOGA'!A:C,3,FALSE)) | E4: =IF(B4="","",VLOOKUP(B4,'TRENUTNA ZALOGA'!A:D,4,FALSE)) | F4: =IF(B4="","",VLOOKUP(B4,'TRENUTNA ZALOGA'!A:E,5,FALSE)) | G4: 325 | H4: 1201/26 | I4: Simon | J4: Voda Rogla
A5: 46254 | B5: 1136 | C5: =IF(B5="","",VLOOKUP(B5,'TRENUTNA ZALOGA'!A:B,2,FALSE)) | D5: =IF(B5="","",VLOOKUP(B5,'TRENUTNA ZALOGA'!A:C,3,FALSE)) | E5: =IF(B5="","",VLOOKUP(B5,'TRENUTNA ZALOGA'!A:D,4,FALSE)) | F5: =IF(B5="","",VLOOKUP(B5,'TRENUTNA ZALOGA'!A:E,5,FALSE)) | G5: 325 | H5: 1200/26 | I5: Simon | J5: Voda Rogla
A6: 46254 | B6: 1136 | C6: =IF(B6="","",VLOOKUP(B6,'TRENUTNA ZALOGA'!A:B,2,FALSE)) | D6: =IF(B6="","",VLOOKUP(B6,'TRENUTNA ZALOGA'!A:C,3,FALSE)) | E6: =IF(B6="","",VLOOKUP(B6,'TRENUTNA ZALOGA'!A:D,4,FALSE)) | F6: =IF(B6="","",VLOOKUP(B6,'TRENUTNA ZALOGA'!A:E,5,FALSE)) | G6: 650 | H6: 1196/26 | I6: Simon | J6: Dana
A7: 46254 | B7: 1136 | C7: =IF(B7="","",VLOOKUP(B7,'TRENUTNA ZALOGA'!A:B,2,FALSE)) | D7: =IF(B7="","",VLOOKUP(B7,'TRENUTNA ZALOGA'!A:C,3,FALSE)) | E7: =IF(B7="","",VLOOKUP(B7,'TRENUTNA ZALOGA'!A:D,4,FALSE)) | F7: =IF(B7="","",VLOOKUP(B7,'TRENUTNA ZALOGA'!A:E,5,FALSE)) | G7: 1050 | H7: 1197/26 | I7: Simon | J7: Dana
A8: 46254 | B8: 1136 | C8: =IF(B8="","",VLOOKUP(B8,'TRENUTNA ZALOGA'!A:B,2,FALSE)) | D8: =IF(B8="","",VLOOKUP(B8,'TRENUTNA ZALOGA'!A:C,3,FALSE)) | E8: =IF(B8="","",VLOOKUP(B8,'TRENUTNA ZALOGA'!A:D,4,FALSE)) | F8: =IF(B8="","",VLOOKUP(B8,'TRENUTNA ZALOGA'!A:E,5,FALSE)) | G8: 1580 | H8: 1198/26 | I8: Simon | J8: Dana
A9: 46254 | B9: 1136 | C9: =IF(B9="","",VLOOKUP(B9,'TRENUTNA ZALOGA'!A:B,2,FALSE)) | D9: =IF(B9="","",VLOOKUP(B9,'TRENUTNA ZALOGA'!A:C,3,FALSE)) | E9: =IF(B9="","",VLOOKUP(B9,'TRENUTNA ZALOGA'!A:D,4,FALSE)) | F9: =IF(B9="","",VLOOKUP(B9,'TRENUTNA ZALOGA'!A:E,5,FALSE)) | G9: 450 | H9: 1199/26 | I9: Simon | J9: Dana
A10: 46254 | B10: 1684 | C10: =IF(B10="","",VLOOKUP(B10,'TRENUTNA ZALOGA'!A:B,2,FALSE)) | D10: =IF(B10="","",VLOOKUP(B10,'TRENUTNA ZALOGA'!A:C,3,FALSE)) | E10: =IF(B10="","",VLOOKUP(B10,'TRENUTNA ZALOGA'!A:D,4,FALSE)) | F10: =IF(B10="","",VLOOKUP(B10,'TRENUTNA ZALOGA'!A:E,5,FALSE)) | G10: 100 | H10: 1107/26 | I10: Simon | J10: Bela design
C11: =IF(B11="","",VLOOKUP(B11,'TRENUTNA ZALOGA'!A:B,2,FALSE))
C12: =IF(B12="","",VLOOKUP(B12,'TRENUTNA ZALOGA'!A:B,2,FALSE))
C13: =IF(B13="","",VLOOKUP(B13,'TRENUTNA ZALOGA'!A:B,2,FALSE))
C14: =IF(B14="","",VLOOKUP(B14,'TRENUTNA ZALOGA'!A:B,2,FALSE))
C15: =IF(B15="","",VLOOKUP(B15,'TRENUTNA ZALOGA'!A:B,2,FALSE))
C16: =IF(B16="","",VLOOKUP(B16,'TRENUTNA ZALOGA'!A:B,2,FALSE))
C17: =IF(B17="","",VLOOKUP(B17,'TRENUTNA ZALOGA'!A:B,2,FALSE))
C18: =IF(B18="","",VLOOKUP(B18,'TRENUTNA ZALOGA'!A:B,2,FALSE))
C19: =IF(B19="","",VLOOKUP(B19,'TRENUTNA ZALOGA'!A:B,2,FALSE))
C20: =IF(B20="","",VLOOKUP(B20,'TRENUTNA ZALOGA'!A:B,2,FALSE))
C21: =IF(B21="","",VLOOKUP(B21,'TRENUTNA ZALOGA'!A:B,2,FALSE))
C22: =IF(B22="","",VLOOKUP(B22,'TRENUTNA ZALOGA'!A:B,2,FALSE))
... C2000: =IF(B2000="","",VLOOKUP(B2000,'TRENUTNA ZALOGA'!A:B,2,FALSE))

Sheet AVGUST 26
A1: Datum | B1: Tip | C1: Šifra materiala | D1: Naziv | E1: Širina | F1: Višina | G1: Gramatura | H1: Količina | I1: Št. Dobavnice / DN | J1: Dobavitelj | K1: Oseba | L1: Opomba
A2: 19. 08. 2026 | B2: PRISPELO | C2: 2295 | D2: Garda matt | E2: 70 | F2: 100 | G2: 250 | H2: 2000 | I2: 2041027777/18.08.2026 | J2: EUROPAPIR D.O.O
A3: 19. 08. 2026 | B3: PRISPELO | C3: 2434 | D3: Magno satin | E3: 64 | F3: 90 | G3: 130 | H3: 2000 | I3: 2041027811/18.08.2026 | J3: EUROPAPIR D.O.O
A4: 20. 08. 2026 | B4: PRISPELO | C4: 1684 | D4: STAFIX-statična folija BELA | E4: 65 | F4: 48 | G4: 250 | H4: 2500 | J4: Stafix ltd
A5: 20. 08. 2026 | B5: ODPIS | C5: 4288 | D5: OFFSET PREPRINT | E5: 45 | F5: 64 | G5: 90 | H5: 650 | I5: 1195/26 | K5: Simon | L5: VENDO
A6: 20. 08. 2026 | B6: ODPIS | C6: 1136 | D6: NiklaSelect | E6: 70 | F6: 100 | G6: 90 | H6: 200 | I6: 1202/26 | K6: Simon | L6: Voda Rogla
A7: 20. 08. 2026 | B7: ODPIS | C7: 1136 | D7: NiklaSelect | E7: 70 | F7: 100 | G7: 90 | H7: 325 | I7: 1201/26 | K7: Simon | L7: Voda Rogla
A8: 20. 08. 2026 | B8: ODPIS | C8: 1136 | D8: NiklaSelect | E8: 70 | F8: 100 | G8: 90 | H8: 325 | I8: 1200/26 | K8: Simon | L8: Voda Rogla
A9: 20. 08. 2026 | B9: ODPIS | C9: 1136 | D9: NiklaSelect | E9: 70 | F9: 100 | G9: 90 | H9: 650 | I9: 1196/26 | K9: Simon | L9: Dana
A10: 20. 08. 2026 | B10: ODPIS | C10: 1136 | D10: NiklaSelect | E10: 70 | F10: 100 | G10: 90 | H10: 1050 | I10: 1197/26 | K10: Simon | L10: Dana
A11: 20. 08. 2026 | B11: ODPIS | C11: 1136 | D11: NiklaSelect | E11: 70 | F11: 100 | G11: 90 | H11: 1580 | I11: 1198/26 | K11: Simon | L11: Dana
A12: 20. 08. 2026 | B12: ODPIS | C12: 1136 | D12: NiklaSelect | E12: 70 | F12: 100 | G12: 90 | H12: 450 | I12: 1199/26 | K12: Simon | L12: Dana
A13: 20. 08. 2026 | B13: ODPIS | C13: 1684 | D13: STAFIX-statična folija BELA | E13: 65 | F13: 48 | G13: 250 | H13: 100 | I13: 1107/26 | K13: Simon | L13: Bela design
