Workbook

Sheet PONUDBA
E1: KALKULACIJA št.: | H1: 1
P2: Datum: | R2: =NOW() -> 45614.789
A3: NAROČNIK: | L3: KOMERCIALIST: | Q3: Tilen Petrič
A4: PONUDBA ZA:
A7: FAZE DELA: | E7: TISK: | F7: Zloženke 149x158 Glyphomax 8 strani
E8: DODELAVA: | F8: razrez+izsek+zgibanje
E12: IZ B1 POLE: | H12: 4 | J12: Format TP: | M12: 500 | N12: x | O12: 350 | Q12: NA TISK. POLI: | U12: 2
E14: Št.TISK. POL: | G14: =IF(H12="","",(ROUNDUP(G19/U12,0))) -> 500 | J14: =IF(H12="","",ROUNDUP(I19/U12,0)) -> 1000 | M14: =M19/U12 -> 1500 | R14: Cena materiala/TONA | Z14: ='CENA MATERIALA'!G4 -> 1500
E15: DODATEK | G15: 200 | J15: 200 | M15: 300
E16: Št. TISK.POL | G16: =IF(G14="","",G14+G15) -> 700 | J16: =IF(J14="","",J14+J15) -> 1200 | M16: =IF(M14="","",M14+M15) -> 1800 | R16: Cena materiala/POLA
E17: POL / RAZREZ: | G17: =IF($H$12="","",(ROUNDUP(G16/$H$12,0))) -> 175 | J17: =IF($H$12="","",(ROUNDUP(J16/$H$12,0))) -> 300 | M17: =IF($H$12="","",(ROUNDUP(M16/$H$12,0))) -> 450
A19: NAKLADA: | G19: 1000 | I19: 2000 | M19: 3000
A20: CENA: | G20: =IF(H35="","",IF(H35=G19,R86)) -> 278.58978 | I20: =IF(I19="","",AP86) -> 304.32074 | M20: =IF(M19="","",BK86) -> 359.90885
A21: CENA ZA KOS: | G21: =IF(G20="","",G20/G19) -> 0.27858978 | I21: =IF(I20="","",I20/I19) -> 0.15216037 | M21: =IF(M20="","",M20/M19) -> 0.11996962
A22: CENA / 1.000: | G22: =IF(G19="","",G21*1000) -> 278.58978 | I22: =IF(I19="","",I21*1000) -> 152.16037 | M22: =IF(M19="","",M21*1000) -> 119.96962
E24: Št.TISK. POL: | G24: =G29/U12 -> 0 | J24: =I29/U12 -> 0 | M24: =M29/U12 -> 0 | P24: ORODJE | R24: =IF(O52="","",IF(O52>0,200)) | S24: =IF(O46="","",IF(O46=1,"",IF(O46=2,"",IF(O46=3,"",IF(O46=4,"",IF(O46=5,200))))))
E25: Z DODATKOM:
E26: Št. TISK.POL | G26: =IF(G24="","",G24+G25) -> 0 | J26: =IF(J24="","",J24+J25) -> 0 | M26: =IF(M24="","",M24+M25) -> 0
E27: POL / RAZREZ: | G27: =IF($H$12="","",(ROUNDUP(G26/$H$12,0))) -> 0 | J27: =IF($H$12="","",(ROUNDUP(J26/$H$12,0))) -> 0 | M27: =IF($H$12="","",(ROUNDUP(M26/$H$12,0))) -> 0
A29: NAKLADA:
A30: CENA: | G30: =IF(G29="","",CG86) | I30: =IF(I29="","",DC86) | M30: =IF(M29="","",DY86)
A31: CENA ZA KOS: | G31: =IF(G30="","",G30/G29) | I31: =IF(I30="","",I30/I29) | M31: =IF(M30="","",M30/M29) | P31: =IF(B37="","",B37)
A32: CENA / 1.000: | G32: =IF(G29="","",G31*1000) | I32: =IF(I29="","",I31*1000) | M32: =IF(M29="","",M31*1000) | P32: =IF(B40="","",B40)
A35: MATERIAL: | H35: =IF(G19="","",G19) -> 1000 | K35: RAZREZ PAPIRJA: | Z35: MATERIAL: | AG35: =IF(I19="","",I19) -> 2000 | AJ35: RAZREZ PAPIRJA: | AU35: MATERIAL: | BB35: =IF(M19="","",M19) -> 3000 | BE35: RAZREZ PAPIRJA: | BP35: MATERIAL: | BW35: =IF(G29="","",G29) | BZ35: RAZREZ PAPIRJA: | CL35: MATERIAL: | CS35: =IF(I29="","",I29) | CV35: RAZREZ PAPIRJA: | DH35: MATERIAL: | DO35: =IF(M29="","",M29) | DR35: RAZREZ PAPIRJA:
B36: Papir: | L36: Razrez 1: | O36: 1 | P36: =IF(O36="","",IF(($H$35/($H$12)/2500)<=0.5,0.25,IF(($H$35/($H$12)/2500)>0.25,($H$35/($H$12)/2500)))) -> 0.25 | R36: =IF(P36="","",(P36*17)) -> 4.25 | AA36: Papir: | AK36: Razrez 1: | AM36: =IF($O$36="","",$O$36) -> 1 | AN36: =IF(AM36="","",IF(($AG$35/($H$12)/2500)<=0.5,0.5,IF(($AG$35/($H$12)/2500)>0.25,($AG$35/($H$12)/2500)))) -> 0.5 | AP36: =IF(AN36="","",(AN36*17)) -> 8.5 | AV36: Papir: | BF36: Razrez 1: | BH36: =IF($O$36="","",$O$36) -> 1 | BI36: =IF(BH36="","",IF(($BB$35/($H$12)/2500)<=0.25,0.5,IF(($BB$35/($H$12)/2500)>0.5,($BB$35/($H$12)/2500)))) -> FALSE | BK36: =IF(BI36="","",(BI36*17)) -> 0 | BQ36: Papir: | CA36: Razrez 1: | CD36: =BH36 -> 1 | CE36: =IF(CD36="","",IF(($BW$35/($H$12)/2500)<=0.5,0.5,IF(($BW$35/($H$12)/2500)>0.25,($BW$35/($H$12)/2500)))) -> #VALUE! | CG36: =IF(CE36="","",(CE36*17)) -> #VALUE! | CM36: Papir: | CW36: Razrez 1: | CZ36: =CD36 -> 1 | DA36: =IF(CZ36="","",IF(($CS$35/($H$12)/2500)<=0.5,0.5,IF(($CS$35/($H$12)/2500)>0.25,($CS$35/($H$12)/2500)))) -> #VALUE! | DC36: =IF(DA36="","",(DA36*17)) -> #VALUE! | DI36: Papir: | DS36: Razrez 1: | DV36: =CZ36 -> 1 | DW36: =IF(DV36="","",IF(($DO$35/($H$12)/2500)<=0.5,0.5,IF(($DO$35/($H$12)/2500)>0.25,($DO$35/($H$12)/2500)))) -> #VALUE! | DY36: =IF(DW36="","",(DW36*17)) -> #VALUE!
G37: 0.1027 | H37: =IF(G37="","",IF($G$37>0,(($G$14+50)/($H$12/$U$12)*$G$37))*1.03) -> 29.089775 | L37: Razrez 2: | P37: =IF(O37="","",IF(($H$35/($H$12)/2500)<=0.25,0.5,IF(($H$35/($H$12)/2500)>0.25,($H$35/($H$12)/2500)))) | R37: =IF(P37="","",(P37*17)) | AA37: =IF(B37="","",B37) | AF37: =IF(G37="","",G37) -> 0.1027 | AG37: =IF(AF37="","",IF($G$37>0,(($J$14+50)/($H$12/$U$12)*$G$37))*1.03) -> 55.535025 | AK37: Razrez 2: | AM37: =IF($O$37="","",$O$37) | AN37: =IF(AM37="","",IF(($AG$35/($H$12)/2500)<=0.5,0.5,IF(($AG$35/($H$12)/2500)>0.25,($AG$35/($H$12)/2500)))) | AP37: =IF(AN37="","",(AN37*17)) | AV37: =IF(B37="","",B37) | BA37: =IF(G37="","",G37) -> 0.1027 | BB37: =IF(BA37="","",IF($G$37>0,(($M$14+50)/($H$12/$U$12)*$G$37))*1.03) -> 81.980275 | BF37: Razrez 2: | BH37: =IF($O$37="","",$O$37) | BI37: =IF(BH37="","",IF(($BB$35/($H$12)/2500)<=0.5,0.5,IF(($BB$35/($H$12)/2500)>0.25,($BB$35/($H$12)/2500)))) | BK37: =IF(BI37="","",(BI37*17)) | BQ37: =AV37 | BV37: =BA37 -> 0.1027 | BW37: =IF(BV37="","",IF($G$37>0,(($G$24+50)/($H$12/$U$12)*$G$37))*1.03) -> 2.644525 | CA37: Razrez 2: | CD37: =BH37 | CE37: =IF(CD37="","",IF(($BW$35/($H$12)/2500)<=0.5,0.5,IF(($BW$35/($H$12)/2500)>0.25,($BW$35/($H$12)/2500)))) | CG37: =IF(CE37="","",(CE37*17)) | CM37: =BQ37 | CR37: =BV37 -> 0.1027 | CS37: =IF(CR37="","",IF($G$37>0,(($J$24+50)/($H$12/$U$12)*$G$37))*1.03) -> 2.644525 | CW37: Razrez 2: | CZ37: =CD37 | DA37: =IF(CZ37="","",IF(($CS$35/($H$12)/2500)<=0.5,0.5,IF(($CS$35/($H$12)/2500)>0.25,($CS$35/($H$12)/2500)))) | DC37: =IF(DA37="","",(DA37*17)) | DI37: =CM37 | DN37: =CR37 -> 0.1027 | DO37: =IF(DN37="","",IF($G$37>0,(($M$24+50)/($H$12/$U$12)*$G$37))*1.03) -> 2.644525 | DS37: Razrez 2: | DV37: =CZ37 | DW37: =IF(DV37="","",IF(($DO$35/($H$12)/2500)<=0.5,0.5,IF(($DO$35/($H$12)/2500)>0.25,($DO$35/($H$12)/2500)))) | DY37: =IF(DW37="","",(DW37*17))
L38: Razrez 3: | P38: =IF(O38="","",IF(($H$35/($H$12)/2000)<=0.5,0.5,IF(($H$35/($H$12)/2000)>0.25,($H$35/($H$12)/2000)))) | R38: =IF(P38="","",(P38*17)) | AK38: Razrez 3: | AM38: =IF($O$38="","",$O$38) | AN38: =IF(AM38="","",IF(($AG$35/($H$12)/2000)<=0.25,0.5,IF(($AG$35/($H$12)/2000)>0.25,($AG$35/($H$12)/2000)))) | AP38: =IF(AN38="","",(AN38*17)) | BF38: Razrez 3: | BH38: =IF($O$38="","",$O$38) | BI38: =IF(BH38="","",IF(($BB$35/($H$12)/2000)<=0.5,0.5,IF(($BB$35/($H$12)/2000)>0.25,($BB$35/($H$12)/2000)))) | BK38: =IF(BI38="","",(BI38*17)) | CA38: Razrez 3: | CD38: =BH38 | CE38: =IF(CD38="","",IF(($BW$35/($H$12)/2000)<=0.5,0.5,IF(($BW$35/($H$12)/2000)>0.25,($BW$35/($H$12)/2000)))) | CG38: =IF(CE38="","",(CE38*17)) | CW38: Razrez 3: | CZ38: =CD38 | DA38: =IF(CZ38="","",IF(($CS$35/($H$12)/2000)<=0.5,0.5,IF(($CS$35/($H$12)/2000)>0.25,($CS35/($H$12)/2000)))) | DC38: =IF(DA38="","",(DA38*17)) | DS38: Razrez 3: | DV38: =CZ38 | DW38: =IF(DV38="","",IF(($DO$35/($H$12)/2000)<=0.5,0.5,IF(($DO$35/($H$12)/2000)>0.25,($DO$35/($H$12)/2000)))) | DY38: =IF(DW38="","",(DW38*17))
B39: Karton: | AA39: Karton: | AV39: Karton: | BQ39: Karton: | CM39: Karton: | DI39: Karton:
H40: =IF(G40="","",IF($G$40>0,(($G$14+50)/($H$12/$U$12)*$G$40))*1.03) | L40: VSOTA: | S40: =SUM(R38,R37,R36) -> 4.25 | AA40: =IF(B40="","",B40) | AF40: =IF(G40="","",G40) | AG40: =IF(AF40="","",IF($G$40>0,(($J$14+50)/($H$12/$U$12)*$G$40))*1.03) | AK40: VSOTA: | AQ40: =SUM(AP38,AP37,AP36) -> 8.5 | AV40: =IF(B40="","",B40) | BA40: =IF($G$40="","",$G$40) | BB40: =IF(BA40="","",IF($G$40>0,(($M$14+50)/($H$12/$U$12)*$G$40))*1.03) | BF40: VSOTA: | BL40: =SUM(BK38,BK37,BK36) -> 0 | BQ40: =AV40 | BV40: =IF($G$40="","",$G$40) | BW40: =IF(BV40="","",IF($G$40>0,(($G$24+50)/($H$12/$U$12)*$G$40))*1.03) | CA40: VSOTA: | CH40: =SUM(CG38,CG37,CG36) -> #VALUE! | CM40: =BQ40 | CR40: =IF($G$40="","",$G$40) | CS40: =IF(CR40="","",IF($G$40>0,(($J$24+50)/($H$12/$U$12)*$G$40))*1.03) | CW40: VSOTA: | DD40: =SUM(DC38,DC37,DC36) -> #VALUE! | DI40: =CM40 | DN40: =IF($G$40="","",$G$40) | DO40: =IF(DN40="","",IF($G$40>0,(($M$24+50)/($H$12/$U$12)*$G$40))*1.03) | DS40: VSOTA: | DZ40: =SUM(DY38,DY37,DY36) -> #VALUE!
B42: VSOTA: | H42: =SUM(H37:H40) -> 29.089775 | AA42: VSOTA: | AG42: =SUM(AG37:AG40) -> 55.535025 | AV42: VSOTA: | BB42: =SUM(BB37:BB40) -> 81.980275 | BQ42: VSOTA: | BW42: =SUM(BW37:BW40) -> 2.644525 | CM42: VSOTA: | CS42: =SUM(CS37:CS40) -> 2.644525 | DI42: VSOTA: | DO42: =SUM(DO37:DO40) -> 2.644525
A45: IZDELAVA TISKOVNE FORME: | K45: TISK / IZSEK / LEPLJENJE | Z45: IZDELAVA TISKOVNE FORME: | AJ45: TISK / IZSEK / LEPLJENJE | AU45: IZDELAVA TISKOVNE FORME: | BE45: TISK / IZSEK / LEPLJENJE | BP45: IZDELAVA TISKOVNE FORME: | BZ45: TISK / IZSEK / LEPLJENJE | CL45: IZDELAVA TISKOVNE FORME: | CV45: TISK / IZSEK / LEPLJENJE | DH45: IZDELAVA TISKOVNE FORME: | DR45: TISK / IZSEK / LEPLJENJE
A46: I T F | B46: Montaža - kopija: | F46: 1 | H46: =IF(F46="","",(F46*17)) -> 17 | K46: D O D E L A V A | L46: CILINDER | O46: 1 | S46: FOLIJA | Z46: I T F | AA46: Montaža - kopija: | AE46: =IF(F46="","",F46) -> 1 | AG46: =IF(AE46="","",(AE46*17)) -> 17 | AJ46: D O D E L A V A | AK46: CILINDER | AM46: =IF(O46="","",O46) -> 1 | AQ46: FOLIJA | AU46: I T F | AV46: Montaža - kopija: | AZ46: =AE46 -> 1 | BB46: =IF(AZ46="","",(AZ46*17)) -> 17 | BE46: D O D E L A V A | BF46: CILINDER | BH46: =IF(O46="","",O46) -> 1 | BL46: FOLIJA | BP46: I T F | BQ46: Montaža - kopija: | BU46: =AZ46 -> 1 | BW46: =IF(BU46="","",(BU46*17)) -> 17 | BZ46: D O D E L A V A | CA46: CILINDER | CD46: =BH46 -> 1 | CH46: FOLIJA | CL46: I T F | CM46: Montaža - kopija: | CQ46: =BU46 -> 1 | CS46: =IF(CQ46="","",(CQ46*17)) -> 17 | CV46: D O D E L A V A | CW46: CILINDER | CZ46: =CD46 -> 1 | DD46: FOLIJA | DH46: I T F | DI46: Montaža - kopija: | DM46: =CQ46 -> 1 | DO46: =IF(DM46="","",(DM46*17)) -> 17 | DR46: D O D E L A V A | DS46: CILINDER | DV46: =CZ46 -> 1 | DZ46: FOLIJA
B47: Plošče: | F47: 9 | H47: =IF(F47="","",F47*13) -> 117 | L47: Priprava: | O47: =IF(O46="","",IF(O46=1,0.5,IF(O46=2,1,IF(O46=3,2,IF(O46=4,0.5,IF(O46=5,1)))))) -> 0.5 | Q47: =IF(O47="","",O47*17) -> 8.5 | AA47: Plošče: | AE47: =IF(F47="","",F47) -> 9 | AG47: =IF(AE47="","",AE47*8) -> 72 | AK47: Priprava: | AM47: =IF(AM46="","",IF(AM46=1,0.5,IF(AM46=2,1,IF(AM46=3,2,IF(AM46=4,0.5,IF(AM46=5,1)))))) -> 0.5 | AO47: =IF(AM47="","",AM47*17) -> 8.5 | AV47: Plošče: | AZ47: =IF(AE47="","",AE47) -> 9 | BB47: =IF(AZ47="","",AZ47*8) -> 72 | BF47: Priprava: | BH47: =IF(BH46="","",IF(BH46=1,0.5,IF(BH46=2,1,IF(BH46=3,2,IF(BH46=4,0.5,IF(BH46=5,1)))))) -> 0.5 | BJ47: =IF(BH47="","",BH47*17) -> 8.5 | BQ47: Plošče: | BU47: =AZ47 -> 9 | BW47: =IF(BU47="","",BU47*8) -> 72 | CA47: Priprava: | CD47: =IF(CD46="","",IF(CD46=1,0.5,IF(CD46=2,1,IF(CD46=3,2,IF(CD46=4,0.5,IF(CD46=5,1)))))) -> 0.5 | CF47: =IF(CD47="","",CD47*17) -> 8.5 | CM47: Plošče: | CQ47: =BU47 -> 9 | CS47: =IF(CQ47="","",CQ47*8) -> 72 | CW47: Priprava: | CZ47: =IF(CZ46="","",IF(CZ46=1,0.5,IF(CZ46=2,1,IF(CZ46=3,2,IF(CZ46=4,0.5,IF(CZ46=5,1)))))) -> 0.5 | DB47: =IF(CZ47="","",CZ47*17) -> 8.5 | DI47: Plošče: | DM47: =CQ47 -> 9 | DO47: =IF(DM47="","",DM47*8) -> 72 | DS47: Priprava: | DV47: =IF(DV46="","",IF(DV46=1,0.5,IF(DV46=2,1,IF(DV46=3,2,IF(DV46=4,0.5,IF(DV46=5,1)))))) -> 0.5 | DX47: =IF(DV47="","",DV47*17) -> 8.5
B48: PC Repro: | F48: 1 | H48: =IF(F48="","",F48*21) -> 21 | L48: Tisk Ž/P: | O48: =IF(O46="","",IF(O46=1,(H35/$U$12)/1000,IF(O46=2,"",IF(O46=3,"",IF(O46=4,(H35/$U$12)/1000*2,IF(O46=5,"")))))) -> 0.5 | Q48: =IF(O48="","",O48*17) -> 8.5 | AA48: PC Repro: | AE48: =IF($F$48="","",$F$48) -> 1 | AG48: =IF(AE48="","",AE48*21) -> 21 | AK48: Tisk Ž/P: | AM48: =IF(AM46="","",IF(AM46=1,(AG35/$U$12)/1000,IF(AM46=2,"",IF(AM46=3,"",IF(AM46=4,(AG35/$U$12)/1000*2,IF(AM46=5,"")))))) -> 1 | AO48: =IF(AM48="","",AM48*17) -> 17 | AV48: PC Repro: | AZ48: =IF($F$48="","",$F$48) -> 1 | BB48: =IF(AZ48="","",AZ48*21) -> 21 | BF48: Tisk Ž/P: | BH48: =IF(BH46="","",IF(BH46=1,(BB35/$U$12)/1000,IF(BH46=2,"",IF(BH46=3,"",IF(BH46=4,(BB35/$U$12)/1000*2,IF(BH46=5,"")))))) -> 1.5 | BJ48: =IF(BH48="","",BH48*17) -> 25.5 | BQ48: PC Repro: | BU48: =IF($F$48="","",$F$48) -> 1 | BW48: =IF(BU48="","",BU48*21) -> 21 | CA48: Tisk Ž/P: | CD48: =IF(CD46="","",IF(CD46=1,(BW35/$U$12)/1000,IF(CD46=2,"",IF(CD46=3,"",IF(CD46=4,(BW35/$U$12)/1000*2,IF(CD46=5,"")))))) -> #VALUE! | CF48: =IF(CD48="","",CD48*17) -> #VALUE! | CM48: PC Repro: | CQ48: =IF($F$48="","",$F$48) -> 1 | CS48: =IF(CQ48="","",CQ48*21) -> 21 | CW48: Tisk Ž/P: | CZ48: =IF(CZ46="","",IF(CZ46=1,(CS35/$U$12)/1000,IF(CZ46=2,"",IF(CZ46=3,"",IF(CZ46=4,(CS35/$U$12)/1000*2,IF(CZ46=5,"")))))) -> #VALUE! | DB48: =IF(CZ48="","",CZ48*17) -> #VALUE! | DI48: PC Repro: | DM48: =IF($F$48="","",$F$48) -> 1 | DO48: =IF(DM48="","",DM48*21) -> 21 | DS48: Tisk Ž/P: | DV48: =IF(DV46="","",IF(DV46=1,(DO35/$U$12)/1000,IF(DV46=2,"",IF(DV46=3,"",IF(DV46=4,(DO35/$U$12)/1000*2,IF(DV46=5,"")))))) -> #VALUE! | DX48: =IF(DV48="","",DV48*17) -> #VALUE!
L49: Tisk folija: | O49: =IF(O46="","",IF(O46=1,"",IF(O46=2,((H35/$U$12)/1000),IF(O46=3,((H35/$U$12)/1000)*2,IF(O46=4,"",IF(O46=5,"")))))) | Q49: =IF(O49="","",O49*17) | S49: =IF(KLIŠE!O5="","",KLIŠE!O5) | AK49: Tisk folija: | AM49: =IF(AM46="","",IF(AM46=1,"",IF(AM46=2,((AG35/$U$12)/1000),IF(AM46=3,((AG35/$U$12)/1000)*2,IF(AM46=4,"",IF(AM46=5,"")))))) | AO49: =IF(AM49="","",AM49*17) | AQ49: =IF($S$49="","",$S$49/$G$19*I19) | BF49: Tisk folija: | BH49: =IF(BH46="","",IF(BH46=1,"",IF(BH46=2,((BB35/$U$12)/1000),IF(BH46=3,((BB35/$U$12)/1000)*2,IF(BH46=4,"",IF(BH46=5,"")))))) | BJ49: =IF(BH49="","",BH49*17) | BL49: =IF($S$49="","",$S$49/$G$19*M19) | CA49: Tisk folija: | CD49: =IF(CD46="","",IF(CD46=1,"",IF(CD46=2,((BW35/$U$12)/1000),IF(CD46=3,((BW35/$U$12)/1000)*2,IF(CD46=4,"",IF(CD46=5,"")))))) | CF49: =IF(CD49="","",CD49*17) | CH49: =IF($S$49="","",$S$49/$G$19*G29) | CW49: Tisk folija: | CZ49: =IF(CZ46="","",IF(CZ46=1,"",IF(CZ46=2,((CS35/$U$12)/1000),IF(CZ46=3,((CS35/$U$12)/1000)*2,IF(CZ46=4,"",IF(CZ46=5,"")))))) | DB49: =IF(CZ49="","",CZ49*17) | DD49: =IF($S$49="","",$S$49/$G$19*I29) | DS49: Tisk folija: | DV49: =IF(DV46="","",IF(DV46=1,"",IF(DV46=2,((DO35/$U$12)/1000),IF(DV46=3,((DO35/$U$12)/1000)*2,IF(DV46=4,"",IF(DV46=5,"")))))) | DX49: =IF(DV49="","",DV49*17) | DZ49: =IF($S$49="","",$S$49/$G$19*M29)
B50: VSOTA: | H50: =SUM(H47:I49) -> 138 | L50: Izsek: | O50: =IF(O46="","",IF(O46=1,"",IF(O46=2,"",IF(O46=3,"",IF(O46=4,"",IF(O46=5,G14/1000)))))) | Q50: =IF(O50="","",O50*17) | AA50: VSOTA: | AG50: =SUM(AG47:AH49) -> 93 | AM50: =IF(AM46="","",IF(AM46=1,"",IF(AM46=2,"",IF(AM46=3,"",IF(AM46=4,"",IF(AM46=5,J14/1000)))))) | AO50: =IF(AM50="","",AM50*17) | AV50: VSOTA: | BB50: =SUM(BB47:BC49) -> 93 | BH50: =IF(BH46="","",IF(BH46=1,"",IF(BH46=2,"",IF(BH46=3,"",IF(BH46=4,"",IF(BH46=5,M14/1000)))))) | BJ50: =IF(BH50="","",BH50*17) | BQ50: VSOTA: | BW50: =SUM(BW47:BX49) -> 93 | CA50: Izsek: | CD50: =IF(CD46="","",IF(CD46=1,"",IF(CD46=2,"",IF(CD46=3,"",IF(CD46=4,"",IF(CD46=5,G24/1000)))))) | CF50: =IF(CD50="","",CD50*17) | CM50: VSOTA: | CS50: =SUM(CS47:CT49) -> 93 | CW50: Izsek: | CZ50: =IF(CZ46="","",IF(CZ46=1,"",IF(CZ46=2,"",IF(CZ46=3,"",IF(CZ46=4,"",IF(CZ46=5,J24/1000)))))) | DB50: =IF(CZ50="","",CZ50*17) | DI50: VSOTA: | DO50: =SUM(DO47:DP49) -> 93 | DS50: Izsek: | DV50: =IF(DV46="","",IF(DV46=1,"",IF(DV46=2,"",IF(DV46=3,"",IF(DV46=4,"",IF(DV46=5,M24/1000)))))) | DX50: =IF(DV50="","",DV50*17)
A52: TISK / STROJ: | L52: BOBST | Z52: TISK / STROJ: | AK52: BOBST | AM52: =IF(O52="","",O52) | AU52: TISK / STROJ: | BF52: BOBST | BH52: =IF(O52="","",O52) | BP52: TISK / STROJ: | CA52: BOBST | CD52: =BH52 | CL52: TISK / STROJ: | CW52: BOBST | CZ52: =CD52 | DH52: TISK / STROJ: | DS52: BOBST | DV52: =CZ52
A53: T I S K | L53: Priprava: | O53: =IF($O$52="","",IF($O$52=1,2,IF($O$52=2,3,IF($O$52=3,4,IF($O$52=4,1.5))))) | Q53: =IF(O53="","",O53*45) | Z53: T I S K | AK53: Priprava: | AM53: =IF($O$52="","",IF($O$52=1,2,IF($O$52=2,3,IF($O$52=3,4,IF($O$52=4,1.5))))) | AO53: =IF(AM53="","",AM53*45) | AU53: T I S K | BF53: Priprava: | BH53: =IF($O$52="","",IF($O$52=1,2,IF($O$52=2,3,IF($O$52=3,4,IF($O$52=4,1.5))))) | BJ53: =IF(BH53="","",BH53*45) | BP53: T I S K | CA53: Priprava: | CD53: =IF($O$52="","",IF($O$52=1,2,IF($O$52=2,3,IF($O$52=3,4,IF($O$52=4,1.5))))) | CF53: =IF(CD53="","",CD53*45) | CL53: T I S K | CW53: Priprava: | CZ53: =IF($O$52="","",IF($O$52=1,2,IF($O$52=2,3,IF($O$52=3,4,IF($O$52=4,1.5))))) | DB53: =IF(CZ53="","",CZ53*45) | DH53: T I S K | DS53: Priprava: | DV53: =IF($O$52="","",IF($O$52=1,2,IF($O$52=2,3,IF($O$52=3,4,IF($O$52=4,1.5))))) | DX53: =IF(DV53="","",DV53*45)
L54: Izsek: | O54: =IF(O52="","",IF(O52=1,H35/($U$12)/3500,IF(O52=2,H35/($U$12)/3500,IF(O52=3,H35/($U$12)/3500*2,IF(O52=4,H35/($U$12)/3500))))) | Q54: =IF(O54="","",O54*45) | AK54: Izsek: | AM54: =IF(AM52="","",IF(AM52=1,AG35/($U$12)/3500,IF(AM52=2,AG35/($U$12)/3500,IF(AM52=3,AG35/($U$12)/3500*2,IF(AM52=4,AG35/($U$12)/3500))))) | AO54: =IF(AM54="","",AM54*45) | BF54: Izsek: | BH54: =IF(BH52="","",IF(BH52=1,BB35/($U$12)/3500,IF(BH52=2,BB35/($U$12)/3500,IF(BH52=3,BB35/($U$12)/3500*2,IF(BH52=4,BB35/($U$12)/3500))))) | BJ54: =IF(BH54="","",BH54*45) | CA54: Izsek: | CD54: =IF(CD52="","",IF(CD52=1,BW35/($U$12)/3500,IF(CD52=2,BW35/($U$12)/3500,IF(CD52=3,BW35/($U$12)/3500*2,IF(CD52=4,BW35/($U$12)/3500))))) | CF54: =IF(CD54="","",CD54*45) | CW54: Izsek: | CZ54: =IF(CZ52="","",IF(CZ52=1,CS35/($U$12)/3500,IF(CZ52=2,CS35/($U$12)/3500,IF(CZ52=3,CS35/($U$12)/3500*2,IF(CZ52=4,CS35/($U$12)/3500))))) | DB54: =IF(CZ54="","",CZ54*45) | DS54: Izsek: | DV54: =IF(DV52="","",IF(DV52=1,DO35/($U$12)/3500,IF(DV52=2,DO35/($U$12)/3500,IF(DV52=3,DO35/($U$12)/3500*2,IF(DV52=4,DO35/($U$12)/3500))))) | DX54: =IF(DV54="","",DV54*45)
B55: S8 | D55: 3 | AA55: H5 | AC55: =IF(D55="","",D55) -> 3 | AV55: H5 | AX55: =IF(D55="","",D55) -> 3 | BQ55: H5 | BS55: =AX55 -> 3 | CM55: H5 | CO55: =BS55 -> 3 | DI55: H5 | DK55: =CO55 -> 3
...

Sheet PLASTIKA
M7: =PONUDBA!M12 -> 500 | N7: x | O7: =PONUDBA!O12 -> 350 | U7: =PONUDBA!U12 -> 2
G9: =PONUDBA!G19 -> 1000 | I9: =PONUDBA!I19:K19 -> 2000 | M9: =PONUDBA!M19:N19 -> 3000
G11: =PONUDBA!G29 -> 0 | I11: =PONUDBA!I29:K29 -> 0 | M11: =PONUDBA!M29:N29 -> 0
A15: PLASTIFICIRANJE
O16: FORMAT TISKOVNE POLE | X16: FORMAT TISKOVNE POLE | AG16: FORMAT TISKOVNE POLE
A17: SIJAJNA | G17: MAT | O17: SIJAJNA PLASTIKA | T17: MAT PLASTIKA | X17: SIJAJNA PLASTIKA | AC17: MAT PLASTIKA | AG17: SIJAJNA PLASTIKA | AL17: MAT PLASTIKA
B18: ŠIRINA: | D18: CENA / m2 | G18: ŠIRINA: | I18: CENA / m2 | O18: =G9/U7 -> 500 | Q18: Delo | T18: =O18 -> 500 | V18: Delo | X18: =I9/U7 -> 1000 | Z18: Delo | AC18: =X18 -> 1000 | AE18: Delo | AG18: =M9/U7 -> 1500 | AI18: Delo | AL18: =AG18 -> 1500 | AN18: Delo
C19: t/m | E19: cena/TM | H19: t/m | J19: cena/TM | O19: =IF($O$7=500,1,IF($O$7=330,2,IF($O$7=350,3))) -> 3 | T19: =O19 -> 3 | X19: =IF($O$7=500,1,IF($O$7=330,2,IF($O$7=350,3))) -> 3 | AC19: =X19 -> 3 | AG19: =IF($O$7=500,1,IF($O$7=330,2,IF($O$7=350,3))) -> 3 | AL19: =AG19 -> 3
B20: 320 | C20: 0.32 | D20: 0.1116 | E20: 0.0357 | G20: 320 | H20: 0.32 | I20: 0.1366 | J20: 0.0437 | O20: 700x500 | P20: =IF($O$19="","",IF($O$19=1,($E$22*(O18*0.7)),"")) | Q20: =IF(P20="","",($O$18/600)*17) | T20: 700x500 | U20: =IF($O$19="","",IF($O$19=1,($J$22*(T18*0.7)),"")) | V20: =IF(U20="","",($T$18/600)*17) | X20: 700x500 | Y20: =IF($O$19="","",IF($O$19=1,($E$22*(X18*0.7)),"")) | Z20: =IF(Y20="","",($X$18/600)*17) | AC20: 700x500 | AD20: =IF($O$19="","",IF($O$19=1,($J$22*(AC18*0.7)),"")) | AE20: =IF(AD20="","",($X$18/600)*17) | AG20: 700x500 | AH20: =IF($O$19="","",IF($O$19=1,($E$22*(AG18*0.7)),"")) | AI20: =IF(AH20="","",($AG$18/600)*17) | AL20: 700x500 | AM20: =IF($O$19="","",IF($O$19=1,($J$22*(AL18*0.7)),"")) | AN20: =IF(AM20="","",($AG$18/600)*17)
B21: 345 | C21: 0.345 | D21: 0.1224 | E21: 0.0422 | G21: 345 | H21: 0.345 | I21: 0.1321 | J21: 0.0455 | K21: Prime zlata | O21: 700x330 | P21: =IF($O$19="","",IF($O$19=1,"",IF($O$19=2,($E$20*(O18*0.7)),""))) | Q21: =IF(P21="","",($O$18/600)*17) | T21: 700x330 | U21: =IF($O$19="","",IF($O$19=1,"",IF($O$19=2,($J$20*(T18*0.7)),""))) | V21: =IF(U21="","",($T$18/600)*17) | X21: 700x330 | Y21: =IF($O$19="","",IF($O$19=1,"",IF($O$19=2,($E$20*(X18*0.7)),""))) | Z21: =IF(Y21="","",($X$18/600)*17) | AC21: 700x330 | AD21: =IF($O$19="","",IF($O$19=1,"",IF($O$19=2,($J$20*(AC18*0.7)),""))) | AE21: =IF(AD21="","",($X$18/600)*17) | AG21: 700x330 | AH21: =IF($O$19="","",IF($O$19=1,"",IF($O$19=2,($E$20*(AG18*0.7)),""))) | AI21: =IF(AH21="","",($AG$18/600)*17) | AL21: 700x330 | AM21: =IF($O$19="","",IF($O$19=1,"",IF($O$19=2,($J$20*(AL18*0.7)),""))) | AN21: =IF(AM21="","",($AG$18/600)*17)
B22: 495 | C22: 0.495 | D22: 0.1151 | E22: 0.0569 | G22: 490 | H22: 0.49 | I22: 0.1265 | J22: 0.0619 | O22: 500x350 | P22: =IF($O$19="","",IF($O$19=1,"",IF($O$19=2,"",IF($O$19=3,($E$21*(O18*0.5)))))) -> 10.55 | Q22: =IF(P22="","",($O$18/700)*17) -> 12.142857 | T22: 500x350 | U22: =IF($O$19="","",IF($O$19=1,"",IF($O$19=2,"",IF($O$19=3,($J$21*(T18*0.5)),"")))) -> 11.375 | V22: =IF(U22="","",($O$18/700)*17) -> 12.142857 | X22: 500x350 | Y22: =IF($O$19="","",IF($O$19=1,"",IF($O$19=2,"",IF($O$19=3,($E$21*(X18*0.5)))))) -> 21.1 | Z22: =IF(Y22="","",($X$18/600)*17) -> 28.333333 | AC22: 500x350 | AD22: =IF($O$19="","",IF($O$19=1,"",IF($O$19=2,"",IF($O$19=3,($J$21*(AC18*0.5)),"")))) -> 22.75 | AE22: =IF(AD22="","",($X$18/700)*17) -> 24.285714 | AG22: 500x350 | AH22: =IF($O$19="","",IF($O$19=1,"",IF($O$19=2,"",IF($O$19=3,($E$21*(AG18*0.5)))))) -> 31.65 | AI22: =IF(AH22="","",($AG$18/700)*17) -> 36.428571 | AL22: 500x350 | AM22: =IF($O$19="","",IF($O$19=1,"",IF($O$19=2,"",IF($O$19=3,($J$21*(AL18*0.5)),"")))) -> 34.125 | AN22: =IF(AM22="","",($AG$18/700)*17) -> 36.428571
G23: 495 | H23: 0.495 | I23: 0.1116 | J23: 0.0552 | O23: SKUPAJ | P23: =SUM(P20:Q22) -> 22.692857 | T23: SKUPAJ | U23: =SUM(U20:V22) -> 23.517857 | X23: SKUPAJ | Y23: =SUM(Y20:Z22) -> 49.433333 | AC23: SKUPAJ | AD23: =SUM(AD20:AE22) -> 47.035714 | AG23: SKUPAJ | AH23: =SUM(AH20:AI22) -> 68.078571 | AL23: SKUPAJ | AM23: =SUM(AM20:AN22) -> 70.553571
A27: KRAZFEST | G27: SOFT TOUCH 4 | O27: KRATZFEST PLASTIKA | T27: SOFT TOUCH PLASTIKA | X27: KRATZFEST PLASTIKA | AC27: SOFT TOUCH PLASTIKA | AG27: KRATZFEST PLASTIKA | AL27: SOFT TOUCH PLASTIKA
B28: ŠIRINA: | D28: CENA / m2 | G28: ŠIRINA: | I28: CENA / m2 | O28: =O18 -> 500 | Q28: Delo | T28: =O18 -> 500 | V28: Delo | X28: =X18 -> 1000 | Z28: Delo | AC28: =X18 -> 1000 | AE28: Delo | AG28: =AG18 -> 1500 | AI28: Delo | AL28: =AG18 -> 1500 | AN28: Delo
C29: tekoči meter | E29: cena/TM | H29: tekoči meter | J29: cena/TM | O29: =O19 -> 3 | T29: =O19 -> 3 | X29: =X19 -> 3 | AC29: =X19 -> 3 | AG29: =AG19 -> 3 | AL29: =AG19 -> 3
B30: 320 | C30: 0.32 | D30: 0.3432 | E30: 0.1098 | G30: 320 | H30: 0.32 | I30: 0.6528 | J30: 0.2088 | O30: 700x500 | P30: =IF($O$19="","",IF($O$19=1,($E$33*(O18*0.7)),"")) | Q30: =IF(P30="","",($O$18/600)*17) | T30: 700x500 | U30: =IF(T29="","",IF(T29=1,($J$33*(O18*0.7)),"")) | V30: =IF(U30="","",($O$28/600)*17) | X30: 700x500 | Y30: =IF($O$19="","",IF($O$19=1,($E$33*(X18*0.7)),"")) | Z30: =IF(Y30="","",($X$18/600)*17) | AC30: 700x500 | AD30: =IF(AC29="","",IF(AC29=1,($J$33*(X18*0.7)),"")) | AE30: =IF(AD30="","",($X$18/600)*17) | AG30: 700x500 | AH30: =IF($O$19="","",IF($O$19=1,($E$33*(AG18*0.7)),"")) | AI30: =IF(AH30="","",($AG$18/600)*17) | AL30: 700x500 | AM30: =IF(AL29="","",IF(AL29=1,($J$33*(AG18*0.7)),"")) | AN30: =IF(AM30="","",($AG$18/600)*17)
B31: 345 | C31: 0.345 | O31: 700x330 | P31: =IF($O$19="","",IF($O$19=1,"",IF($O$19=2,($E$30*(O18*0.7)),""))) | Q31: =IF(P31="","",($O$18/600)*17) | T31: 700x330 | U31: =IF(O29="","",IF(T29=1,"",IF(T29=2,($J$30*(T18*0.7)),""))) | V31: =IF(U31="","",($O$28/600)*17) | X31: 700x330 | Y31: =IF($O$19="","",IF($O$19=1,"",IF($O$19=2,($E$30*(X18*0.7)),""))) | Z31: =IF(Y31="","",($X$18/600)*17) | AC31: 700x330 | AD31: =IF(X29="","",IF(AC29=1,"",IF(AC29=2,($J$30*(AC18*0.7)),""))) | AE31: =IF(AD31="","",($X$18/600)*17) | AG31: 700x330 | AH31: =IF($O$19="","",IF($O$19=1,"",IF($O$19=2,($E$30*(AG18*0.7)),""))) | AI31: =IF(AH31="","",($AG$18/600)*17) | AL31: 700x330 | AM31: =IF(AG29="","",IF(AL29=1,"",IF(AL29=2,($J$30*(AL18*0.7)),""))) | AN31: =IF(AM31="","",($AG$18/600)*17)
B32: 490 | C32: 0.49 | D32: 0.3154 | E32: 0.1545 | O32: 500x350 | P32: =IF($O$19="","",IF($O$19=1,"",IF($O$19=2,"",IF($O$19=3,($E$30*(O18*0.5)))))) -> 27.45 | Q32: =IF(P32="","",($O$18/700)*17) -> 12.142857 | T32: 500x350 | U32: =IF(O29="","",IF(T29=1,"",IF(T29=2,"",IF(T29=3,($J$30*(T28*0.5)),"")))) -> 52.2 | V32: =IF(U32="","",($O$18/700)*17) -> 12.142857 | X32: 500x350 | Y32: =IF($O$19="","",IF($O$19=1,"",IF($O$19=2,"",IF($O$19=3,($E$30*(X18*0.5)))))) -> 54.9 | Z32: =IF(Y32="","",($X$18/700)*17) -> 24.285714 | AC32: 500x350 | AD32: =IF(X29="","",IF(AC29=1,"",IF(AC29=2,"",IF(AC29=3,($J$30*(AC28*0.5)),"")))) -> 104.4 | AE32: =IF(AD32="","",($X$18/700)*17) -> 24.285714 | AG32: 500x350 | AH32: =IF($O$19="","",IF($O$19=1,"",IF($O$19=2,"",IF($O$19=3,($E$30*(AG18*0.5)))))) -> 82.35 | AI32: =IF(AH32="","",($AG$18/700)*17) -> 36.428571 | AL32: 500x350 | AM32: =IF(AG29="","",IF(AL29=1,"",IF(AL29=2,"",IF(AL29=3,($J$30*(AL28*0.5)),"")))) -> 156.6 | AN32: =IF(AM32="","",($AG$18/700)*17) -> 36.428571
B33: 495 | C33: 0.495 | D33: 0.51 | E33: 0.2524 | G33: 495 | H33: 0.495 | I33: 0.5814 | J33: 0.2877 | O33: SKUPAJ | P33: =SUM(P30:Q32) -> 39.592857 | T33: SKUPAJ | U33: =SUM(U30:V32) -> 64.342857 | X33: SKUPAJ | Y33: =SUM(Y30:Z32) -> 79.185714 | AC33: SKUPAJ | AD33: =SUM(AD30:AE32) -> 128.68571 | AG33: SKUPAJ | AH33: =SUM(AH30:AI32) -> 118.77857 | AL33: SKUPAJ | AM33: =SUM(AM30:AN32) -> 193.02857
O36: FORMAT TISKOVNE POLE | X36: FORMAT TISKOVNE POLE | AG36: FORMAT TISKOVNE POLE
O37: SIJAJNA PLASTIKA | T37: MAT PLASTIKA | X37: SIJAJNA PLASTIKA | AC37: MAT PLASTIKA | AG37: SIJAJNA PLASTIKA | AL37: MAT PLASTIKA
O38: =G11/U7 -> 0 | Q38: Delo | T38: =O38 -> 0 | V38: Delo | X38: =I11/U7 -> 0 | Z38: Delo | AC38: =X38 -> 0 | AE38: Delo | AG38: =M11/U7 -> 0 | AI38: Delo | AL38: =AG38 -> 0 | AN38: Delo
O39: =IF($O$7=500,1,IF($O$7=330,2,IF($O$7=350,3))) -> 3 | T39: =O39 -> 3 | X39: =IF($O$7=500,1,IF($O$7=330,2,IF($O$7=350,3))) -> 3 | AC39: =X39 -> 3 | AG39: =IF($O$7=500,1,IF($O$7=330,2,IF($O$7=350,3))) -> 3 | AL39: =AG39 -> 3
O40: 700x500 | P40: =IF($O$19="","",IF($O$19=1,($E$22*(O38*0.7)),"")) | Q40: =IF(P40="","",($O$18/600)*17) | T40: 700x500 | U40: =IF($O$19="","",IF($O$19=1,($J$22*(T38*0.7)),"")) | V40: =IF(U40="","",($T$18/600)*17) | X40: 700x500 | Y40: =IF($O$19="","",IF($O$19=1,($E$22*(X38*0.7)),"")) | Z40: =IF(Y40="","",($X$18/600)*17) | AC40: 700x500 | AD40: =IF($O$19="","",IF($O$19=1,($J$22*(AC38*0.7)),"")) | AE40: =IF(AD40="","",($X$18/600)*17) | AG40: 700x500 | AH40: =IF($O$19="","",IF($O$19=1,($E$22*(AG38*0.7)),"")) | AI40: =IF(AH40="","",($AG$18/600)*17) | AL40: 700x500 | AM40: =IF($O$19="","",IF($O$19=1,($J$22*(AL38*0.7)),"")) | AN40: =IF(AM40="","",($AG$18/600)*17)
O41: 700x330 | P41: =IF($O$19="","",IF($O$19=1,"",IF($O$19=2,($E$20*(O38*0.7)),""))) | Q41: =IF(P41="","",($O$38/600)*17) | T41: 700x330 | U41: =IF($O$19="","",IF($O$19=1,"",IF($O$19=2,($J$20*(T38*0.7)),""))) | V41: =IF(U41="","",($T$38/600)*17) | X41: 700x330 | Y41: =IF($O$19="","",IF($O$19=1,"",IF($O$19=2,($E$20*(X38*0.7)),""))) | Z41: =IF(Y41="","",($X$18/600)*17) | AC41: 700x330 | AD41: =IF($O$19="","",IF($O$19=1,"",IF($O$19=2,($J$20*(AC38*0.7)),""))) | AE41: =IF(AD41="","",(AC38/600)*17) | AG41: 700x330 | AH41: =IF($O$19="","",IF($O$19=1,"",IF($O$19=2,($E$20*(AG38*0.7)),""))) | AI41: =IF(AH41="","",($AG$18/600)*17) | AL41: 700x330 | AM41: =IF($O$19="","",IF($O$19=1,"",IF($O$19=2,($J$20*(AL38*0.7)),""))) | AN41: =IF(AM41="","",($AG$38/600)*17)
O42: 500x350 | P42: =IF($O$19="","",IF($O$19=1,"",IF($O$19=2,"",IF($O$19=3,($E$21*(O38*0.5)))))) -> 0 | Q42: =IF(P42="","",($O$18/700)*17) -> 12.142857 | T42: 500x350 | U42: =IF($O$19="","",IF($O$19=1,"",IF($O$19=2,"",IF($O$19=3,($J$21*(T38*0.5)),"")))) -> 0 | V42: =IF(U42="","",($O$18/700)*17) -> 12.142857 | X42: 500x350 | Y42: =IF($O$19="","",IF($O$19=1,"",IF($O$19=2,"",IF($O$19=3,($E$21*(X38*0.5)))))) -> 0 | Z42: =IF(Y42="","",($X$18/600)*17) -> 28.333333 | AC42: 500x350 | AD42: =IF($O$19="","",IF($O$19=1,"",IF($O$19=2,"",IF($O$19=3,($J$21*(AC38*0.5)),"")))) -> 0 | AE42: =IF(AD42="","",($X$18/700)*17) -> 24.285714 | AG42: 500x350 | AH42: =IF($O$19="","",IF($O$19=1,"",IF($O$19=2,"",IF($O$19=3,($E$21*(AG38*0.5)))))) -> 0 | AI42: =IF(AH42="","",($AG$18/700)*17) -> 36.428571 | AL42: 500x350 | AM42: =IF($O$19="","",IF($O$19=1,"",IF($O$19=2,"",IF($O$19=3,($J$21*(AL38*0.5)),"")))) -> 0 | AN42: =IF(AM42="","",($AG$18/700)*17) -> 36.428571
O43: SKUPAJ | P43: =SUM(P40:Q42) -> 12.142857 | T43: SKUPAJ | U43: =SUM(U40:V42) -> 12.142857 | X43: SKUPAJ | Y43: =SUM(Y40:Z42) -> 28.333333 | AC43: SKUPAJ | AD43: =SUM(AD40:AE42) -> 24.285714 | AG43: SKUPAJ | AH43: =SUM(AH40:AI42) -> 36.428571 | AL43: SKUPAJ | AM43: =SUM(AM40:AN42) -> 36.428571
O47: KRATZFEST PLASTIKA | T47: SOFT TOUCH PLASTIKA | X47: KRATZFEST PLASTIKA | AC47: SOFT TOUCH PLASTIKA | AG47: KRATZFEST PLASTIKA | AL47: SOFT TOUCH PLASTIKA
O48: =O38 -> 0 | Q48: Delo | T48: =O38 -> 0 | V48: Delo | X48: =X38 -> 0 | Z48: Delo | AC48: =X38 -> 0 | AE48: Delo | AG48: =AG38 -> 0 | AI48: Delo | AL48: =AG38 -> 0 | AN48: Delo
O49: =O39 -> 3 | T49: =O39 -> 3 | X49: =X39 -> 3 | AC49: =X39 -> 3 | AG49: =AG39 -> 3 | AL49: =AG39 -> 3
O50: 700x500 | P50: =IF($O$19="","",IF($O$19=1,($E$33*(O38*0.7)),"")) | Q50: =IF(P50="","",($O$18/600)*17) | T50: 700x500 | U50: =IF(T49="","",IF(T49=1,($J$33*(O38*0.7)),"")) | V50: =IF(U50="","",($O$28/600)*17) | X50: 700x500 | Y50: =IF($O$19="","",IF($O$19=1,($E$33*(X38*0.7)),"")) | Z50: =IF(Y50="","",($X$18/600)*17) | AC50: 700x500 | AD50: =IF(AC49="","",IF(AC49=1,($J$33*(X38*0.7)),"")) | AE50: =IF(AD50="","",($X$18/600)*17) | AG50: 700x500 | AH50: =IF($O$19="","",IF($O$19=1,($E$33*(AG38*0.7)),"")) | AI50: =IF(AH50="","",($AG$18/600)*17) | AL50: 700x500 | AM50: =IF(AL49="","",IF(AL49=1,($J$33*(AG38*0.7)),"")) | AN50: =IF(AM50="","",($AG$18/600)*17)
O51: 700x330 | P51: =IF($O$19="","",IF($O$19=1,"",IF($O$19=2,($E$30*(O38*0.7)),""))) | Q51: =IF(P51="","",(O48/600)*17) | T51: 700x330 | U51: =IF(O49="","",IF(T49=1,"",IF(T49=2,($J$30*(T38*0.7)),""))) | V51: =IF(U51="","",(T48/600)*17) | X51: 700x330 | Y51: =IF($O$19="","",IF($O$19=1,"",IF($O$19=2,($E$30*(X38*0.7)),""))) | Z51: =IF(Y51="","",($X$48/600)*17) | AC51: 700x330 | AD51: =IF(X49="","",IF(AC49=1,"",IF(AC49=2,($J$30*(AC38*0.7)),""))) | AE51: =IF(AD51="","",($AC$48/600)*17) | AG51: 700x330 | AH51: =IF($O$19="","",IF($O$19=1,"",IF($O$19=2,($E$30*(AG38*0.7)),""))) | AI51: =IF(AH51="","",($AG$48/600)*17) | AL51: 700x330 | AM51: =IF(AG49="","",IF(AL49=1,"",IF(AL49=2,($J$30*(AL38*0.7)),""))) | AN51: =IF(AM51="","",($AL$48/600)*17)
O52: 500x350 | P52: =IF($O$19="","",IF($O$19=1,"",IF($O$19=2,"",IF($O$19=3,($E$30*(O38*0.5)))))) -> 0 | Q52: =IF(P52="","",($O$18/700)*17) -> 12.142857 | T52: 500x350 | U52: =IF(O49="","",IF(T49=1,"",IF(T49=2,"",IF(T49=3,($J$30*(T48*0.5)),"")))) -> 0 | V52: =IF(U52="","",($O$18/700)*17) -> 12.142857 | X52: 500x350 | Y52: =IF($O$19="","",IF($O$19=1,"",IF($O$19=2,"",IF($O$19=3,($E$30*(X38*0.5)))))) -> 0 | Z52: =IF(Y52="","",($X$18/700)*17) -> 24.285714 | AC52: 500x350 | AD52: =IF(X49="","",IF(AC49=1,"",IF(AC49=2,"",IF(AC49=3,($J$30*(AC48*0.5)),"")))) -> 0 | AE52: =IF(AD52="","",($X$18/700)*17) -> 24.285714 | AG52: 500x350 | AH52: =IF($O$19="","",IF($O$19=1,"",IF($O$19=2,"",IF($O$19=3,($E$30*(AG38*0.5)))))) -> 0 | AI52: =IF(AH52="","",($AG$18/700)*17) -> 36.428571 | AL52: 500x350 | AM52: =IF(AG49="","",IF(AL49=1,"",IF(AL49=2,"",IF(AL49=3,($J$30*(AL48*0.5)),"")))) -> 0 | AN52: =IF(AM52="","",($AG$18/700)*17) -> 36.428571
O53: SKUPAJ | P53: =SUM(P50:Q52) -> 12.142857 | T53: SKUPAJ | U53: =SUM(U50:V52) -> 12.142857 | X53: SKUPAJ | Y53: =SUM(Y50:Z52) -> 24.285714 | AC53: SKUPAJ | AD53: =SUM(AD50:AE52) -> 24.285714 | AG53: SKUPAJ | AH53: =SUM(AH50:AI52) -> 36.428571 | AL53: SKUPAJ | AM53: =SUM(AM50:AN52) -> 36.428571

Sheet KLIŠE
E2: Fiksna cena klišeja do 30 cm2 | H2: =(C17+C18+C19+C20) -> 27.3 | Z2: 1 ROLA 7.342 dm2
E3: Vsak nadaljni cm2 | H3: 0.26 | O3: IZRAČUN FOLIJE:
E4: IZRAČUN CENE KLIŠEJA: | O4: =IF(E6="","",((H7*0.0095))) | T4: x | U4: 1
E5: VELIKOST: | O5: =IF(H8="","",((O4*PONUDBA!$G$19)*1.1)) | U5: Cena za prvo naklado
F6: x | H6: =IF(E6="","",IF(E6*G6<30,30,(E6*G6))) | Z6: =IF(H11="","",H11)
H7: =IF(E6="","",(E6*G6)/100)
E8: CENA ZA KLIŠE: | H8: =IF(H6="","",IF(H6<=30,H2,H6*H3+H2)) | O8: =IF(H7="","",(H7*PONUDBA!G19)*1.05) | U8: PORABA v DM2
E9: ŠTEVILO KLIŠEJEV:
E11: CENA SKUPAJ: | H11: =IF(H9="",H8,H8*H9)
B16: Cenik klišejev | E16: Velikost klišeja
B17: Film | C17: 7.8 | E17: a | F17: x | G17: b
B18: Faseta | C18: 2.5 | E18: 100 | F18: x | G18: 190 | H18: = | I18: =E18*G18/100 -> 190 | N18: cm2
B19: Pošta | C19: 4.5 | E19: mm | G19: mm
B20: do 30cm2 | C20: 12.5
E21: Cena klišeja
B22: Osnovni stroški | C22: =SUM(C17:C19) -> 14.8 | E22: =C22 -> 14.8 | F22: + | G22: =C23*(I18-30)+C20 -> 54.1 | H22: = | I22: =E22+G22 -> 68.9
B23: vsak nadaljnji cm | C23: 0.26
R29: =IF(O4="","",O4)

Sheet  UV ZUNANJI
A2: Cenik plastificiranja, uv lakiranja in parcialnega uv lakiranja | H2: Količina pol:
H3: 500
A4: Plastificiranje: | B4: Grafoplast d.o.o., Šolska ulica 13, 3210 Sl. Konjice | P4: CENA FOLIJE - rola
B5: T.: 03 759 22 44, Fax: 03 759 22 45, GSM: 040 233 006, mateja@arsstudio.si | M5: Cena usluge | Q5: 3000 | R5: 3000 | S5: 2000 | T5: 2000 | U5: dožina
D6: Cena usluge | J6: Sijaj | K6: Mat | L6: kratzfest | M6: soft touch | N6: Delo | Q6: Sijaj | R6: Mat | S6: kratzfest | T6: soft touch
A7: Cenik: | B7: Sijaj | C7: Mat | D7: Sijaj | E7: Mat | I7: Tek. Metr
A8: B4 | B8: 0.027 | C8: 0.037 | D8: =B8*H3 -> 13.5 | E8: =H3*C8 -> 18.5
A9: B3 | B9: 0.03 | C9: 0.046 | D9: =B9*H3 -> 15 | E9: =C9*H3 -> 23
A10: B2 | B10: 0.046 | C10: 0.067 | D10: =B10*H3 -> 23 | E10: =C10*H3 -> 33.5 | I10: =H3*0.7 -> 350 | L10: =I10*(S10/S5)+N10 -> 60.851923 | M10: =I10*(T10/T5)+N10 -> 116.32692 | N10: =H3/650*17 -> 13.076923 | S10: 273 | T10: 590 | U10: Širina 500
A11: B1 | B11: 0.093 | C11: 0.136 | D11: =B11*H3 -> 46.5 | E11: =C11*H3 -> 68
A12: 700x330 | B12: 0.037 | C12: 0.057 | D12: =B12*H3 -> 18.5 | E12: =C12*H3 -> 28.5 | I12: =H3*0.7 -> 350 | J12: =I12*(Q12/Q5)+N12 -> 25.58009 | K12: =I12*(R12/R5)+N12 -> 37.16859 | L12: =I12*(S12/S5)+N12 -> 49.602923 | M12: =I12*(T12/T5)+N12 -> 74.326923 | N12: =H3/650*17 -> 13.076923 | Q12: 107.17 | R12: 206.5 | S12: 208.72 | T12: 350 | U12: Širina 320
A13: 450x320 | B13: 0.032 | C13: 0.04 | D13: =B13*H3 -> 16 | E13: =C13*H3 -> 20
A14: 640x440 | B14: 0.043 | C14: 0.062 | D14: =B14*H3 -> 21.5 | E14: =C14*H3 -> 31
A15: 900x640 | B15: 0.085 | C15: 0.13 | D15: =B15*H3 -> 42.5 | E15: =C15*H3 -> 65
A16: Prip. str. do 500 pol | B16: 20 | C16: 20
B18: PAM PLUS d.o.o.
B19: T.: 031 677 071, pamef@siol.net
A20: UV lakiranje - FLEHA 1/0 | H20: F7402 | I20: Folija za plastificiranje | J20: SAIJAJ | K20: 320
A21: 500x350 | B21: 0.033 | E21: =(B21*H3)+B25 -> 26.5 | K21: 490
A22: 640x440 | B22: 0.041 | E22: =(B22*H3)+B25 -> 30.5 | H22: F7399 | K22: 495
A23: 700x500 | B23: 0.044 | E23: =(B23*H3)+B25 -> 32 | H23: F7122 | I23: Folija za plastificiranje MAT | K23: 320 | Q23: 0.0357 | S23: 0.0793 | T23: 0.1071
A24: 1000x700 | B24: 0.066 | E24: =(B24*H3)+B25 -> 43 | H24: F7646 | K24: 345
A25: Priprava | B25: 10 | H25: F7400, F7411 | K25: 495
B27: Ditis d.o.o., Stara cesta 20, 2311 Hoče
B28: T.: 041 383 799, ivan.zuran@gmail.com
A29: UV lakiranje - PARCIALNO | B29: Odtis | C29: film | D29: priprava
A30: SIJAJNO 500x350 | B30: 0.079 | C30: 16 | D30: 26.5 | E30: =(B30*H3)+C30+D30 -> 82
A31: do 30% 640x440 | B31: 0.091 | C31: 21 | D31: 31.5 | E31: =(B31*H3)+C31+D31 -> 98
A32: pokritosti 700x500 | B32: 0.097 | C32: 21 | D32: 31.5 | E32: =(B32*H3)+C32+D32 -> 101
A33: 880x640 | B33: 0.1 | C33: 31 | D33: 37 | E33: =(B33*H3)+C33+D33 -> 118
A34: 1000x700 | B34: 0.14 | C34: 40 | D34: 42 | E34: =(B34*H3)+C34+D34 -> 152
A36: UV lakiranje - PARCIALNO | B36: Odtis | C36: film | D36: priprava
A37: MAT 500x350 | B37: =B30*1.3 -> 0.1027 | C37: 16 | D37: 26.5 | E37: =(B37*H3)+C37+D37 -> 93.85
A38: 640x440 | B38: =B31*1.3 -> 0.1183 | C38: 21 | D38: 31.5 | E38: =(B38*H3)+C38+D38 -> 111.65
A39: 700x500 | B39: =B32*1.3 -> 0.1261 | C39: 21 | D39: 31.5 | E39: =(B39*H3)+C39+D39 -> 115.55
A40: 880x640 | B40: =B33*1.3 -> 0.13 | C40: 31 | D40: 37 | E40: =(B40*H3)+C40+D40 -> 133
A41: 1000x700 | B41: =B34*1.3 -> 0.182 | C41: 40 | D41: 42 | E41: =(B41*H3)+C41+D41 -> 173
A44: UV lakiranje - PARCIALNO | B44: Odtis | C44: film | D44: priprava
A45: SIJAJNO 500x350 | B45: =B30*2 -> 0.158 | C45: 16 | D45: 26.5 | E45: =(B45*H3)+C45+D45 -> 121.5
A46: do 60% 640x440 | B46: =B31*2 -> 0.182 | C46: 21 | D46: 31.5 | E46: =(B46*H3)+C46+D46 -> 143.5
...

Sheet BROŠURE
A1: PONUDBA ZA BROŠURE / LETAKE / DOPISE | CH1: IZ B1 = TP 700x500 | CU1: 2 | CY1: 1 | CZ1: ŠT. POL A/B : | DL1: 3
CH2: IZ B1 = TP 700x330 | CU2: 3 | CY2: 2 | CZ2: ŠT. POL A/Obr. : | DL2: 1
A3: NAROČNIK: | AV3: KOMERCIALIST: | BE3: Rok Kadilnik | CH3: IZ B1 = TP 500x350 | CU3: 4
A4: PONUDBA ZA: | CH4: IZ B1 = TP 350x250 | CU4: 8
A5: FAZE DELA:
CH6: SKUPNO ŠT. STRANI: | CT6: 60
A7: TISK: | CH7: ŠT. STRANI NA POLI: | CT7: 16
A8: DODELAVA: | CH8: ŠTEVILO CELIH POL: | CT8: =IF($CT$6="","",(ROUNDDOWN($CT$6/$CT$7,0))) -> 3 | CY8: 3 | CZ8: ŠT. POL A/0 :
CH9: ŠT.STR. NA POLI /Obr.: | CT9: 8
CH10: ŠTEVILO POL/Obr.: | CT10: 1 | CZ10: ŠT. STR. OVITEK
A11: NAKLADA: | J11: 4800 | AG11: TP VLOŽEK: | AM11: 700 | AO11: x | AP11: 500 | AS11: Iz B1: | AV11: 2 | CY11: 1 | CZ11: OVITEK A/B
A12: CENA: | J12: =IF(J11="","",SUM(U28,H43,AA69,J62,T37)) -> 1257.3314 | Q12: =IF(Q11="","",SUM(AS43,BL69,AT62,BE37,BF28)) | X12: =IF(X11="","",SUM(CQ28,CP37,CD43,CW69,CE62)) | AG12: TP OVITEK: | AM12: 700 | AO12: x | AP12: 500 | AS12: Iz B1: | AV12: 2 | CY12: 2 | CZ12: OVITEK A/Obr.
A13: CENA ZA KOS: | J13: =IF(J11="","",J12/J11) -> 0.26194405 | Q13: =IF(Q11="","",Q12/Q11) | X13: =IF(X11="","",X12/X11) | CY13: 3 | CZ13: OVITEK A/0 | DL13: 1
AG14: Vložek: | AK14: =IF(E23="","",E23) -> nivis mat 90g
A15: NAKLADA: | AG15: Ovitek: | AK15: =IF(E32="","",E32) -> incada 250g | CY15: 1 | CZ15: DOPISI A/B
A16: CENA: | J16: =IF(J15="","",SUM(EC28,EB37,DP43,EI69,DQ62)) | Q16: =IF(Q15="","",SUM(FP28,FO37,FC43,FD62,FV69)) | X16: =IF(X15="","",SUM(HC28,HB37,GP43,GQ62,HI69)) | CY16: 2 | CZ16: DOPISI A/Obr.:
A17: CENA ZA KOS: | J17: =IF(J15="","",J16/J15) | Q17: =IF(Q15="","",Q16/Q15) | X17: =IF(X15="","",X16/X15) | CY17: 3 | CZ17: DOPISI A/0
A21: MATERIAL Brošure vložek: | O21: =E23 -> nivis mat 90g | AA21: MATERIAL Ovitek: | AL21: =L30 -> incada 250g
I22: =J11 -> 4800 | AT22: =Q11 -> 0 | CE22: =X11 -> 0 | DQ22: =IF(J15="","",J15) | FD22: =IF(Q15="","",Q15) | GQ22: =IF(X15="","",X15)
A23: Papir: | E23: nivis mat 90g | O23: 0.074 | T23: 1 | U23: =IF($T$23="","",IF($T$23=1,(($J$11*$DL$1)/$AV$11),IF($T$23=2,(($J$11/2)*$DL$2),IF($T$23=3,(($J$11/$AV$11)*$DL$8))))*$O$23*1.05) -> 559.44 | AC23: RAZREZ materiala: | AL23: Papir: | AP23: =IF($E$23="","",$E$23) -> nivis mat 90g | AZ23: =IF($O$23="","",$O$23) -> 0.074 | BE23: =IF($T$23="","",$T$23) -> 1 | BF23: =IF($T$23="","",IF($T$23=1,(($Q$11*$DL$1)/$AV$11),IF($T$23=2,(($Q$11/2)*$DL$2),IF($T$23=3,(($Q$11/$AV$11)*$DL$3))))*$O$23*1.05) -> 0 | BN23: RAZREZ materiala: | BW23: Papir: | CA23: =IF($E$23="","",$E$23) -> nivis mat 90g | CK23: =IF($O$23="","",$O$23) -> 0.074 | CP23: =IF($T$23="","",$T$23) -> 1 | CQ23: =IF($T$23="","",IF($T$23=1,(($X$11*$DL$1)/$AV$11),IF($T$23=2,(($X$11/2)*$DL$2),IF($T$23=3,(($X$11/$AV$11)*$DL$8))))*$O$23*1.05) -> 0 | CY23: RAZREZ materiala: | DI23: Papir: | DM23: =IF($E$23="","",$E$23) -> nivis mat 90g | DW23: =IF($O$23="","",$O$23) -> 0.074 | EB23: =IF($T$23="","",$T$23) -> 1 | EC23: =IF($T$23="","",IF($T$23=1,(($J$15*$DL$1)/$AV$11),IF($T$23=2,(($J$15/2)*$DL$2),IF($T$23=3,(($J$15/$AV$11)*$DL$8))))*$O$23*1.05) -> 0 | EK23: RAZREZ materiala: | EV23: Papir: | EZ23: =IF($E$23="","",$E$23) -> nivis mat 90g | FJ23: =IF($O$23="","",$O$23) -> 0.074 | FO23: =IF($T$23="","",$T$23) -> 1 | FP23: =IF($T$23="","",IF($T$23=1,(($Q$11*$DL$1)/$AV$11),IF($T$23=2,(($Q$11/2)*$DL$2),IF($T$23=3,(($Q$11/$AV$11)*$DL$3))))*$O$23*1.05) -> 0 | FX23: RAZREZ materiala: | GI23: Papir: | GM23: =IF($E$23="","",$E$23) -> nivis mat 90g | GW23: =IF($O$23="","",$O$23) -> 0.074 | HB23: =IF($T$23="","",$T$23) -> 1 | HC23: =IF($T$23="","",IF($T$23=1,(($X$11*$DL$1)/$AV$11),IF($T$23=2,(($X$11/2)*$DL$2),IF($T$23=3,(($X$11/$AV$11)*$DL$8))))*$O$23*1.05) -> 0 | HK23: RAZREZ materiala:
A24: Folija: | AC24: Papir: | AG24: =IF($O$23="","",(($J$11/$AV$11)/3500)*17*CT8*CT10) -> 34.971429 | AL24: Folija: | AP24: =IF($E$24="","",$E$24) | AZ24: =IF($O$24="","",$O$24) | BN24: Papir: | BR24: =IF($O$23="","",(($Q$11/$AV$11)/3500)*17) -> 0 | BW24: Folija: | CA24: =IF($E$24="","",$E$24) | CK24: =IF($O$24="","",$O$24) | CY24: Papir: | DC24: =IF($O$23="","",(($X$11/$AV$11)/3500)*17) -> 0 | DI24: Folija: | DM24: =IF($E$24="","",$E$24) | DW24: =IF($O$24="","",$O$24) | EK24: Papir: | EO24: =IF($O$23="","",(($J$15/$AV$11)/3500)*17) -> 0 | EV24: Folija: | EZ24: =IF($E$24="","",$E$24) | FJ24: =IF($O$24="","",$O$24) | FX24: Papir: | GB24: =IF($O$23="","",(($Q$15/$AV$11)/3500)*17) -> 0 | GI24: Folija: | GM24: =IF($E$24="","",$E$24) | GW24: =IF($O$24="","",$O$24) | HK24: Papir: | HO24: =IF($O$23="","",(($X$15/$AV$11)/3500)*17) -> 0
A25: UV: | AC25: Karton: | AG25: =IF($O$32="","",(($J$11/$AV$12)/2500)*17) -> 16.32 | AL25: UV: | AP25: =IF($E$25="","",$E$25) | AZ25: =IF($O$25="","",$O$25) | BN25: Karton: | BR25: =IF($O$32="","",(($Q$11/$AV$12)/2500)*17) -> 0 | BW25: UV: | CA25: =IF($E$25="","",$E$25) | CK25: =IF($O$25="","",$O$25) | CY25: Karton: | DC25: =IF($O$32="","",(($X$11/$AV$12)/2500)*17) -> 0 | DI25: UV: | DM25: =IF($E$25="","",$E$25) | DW25: =IF($O$25="","",$O$25) | EK25: Karton: | EO25: =IF($O$32="","",(($J$15/$AV$12)/2500)*17) -> 0 | EV25: UV: | EZ25: =IF($E$25="","",$E$25) | FJ25: =IF($O$25="","",$O$25) | FX25: Karton: | GB25: =IF($O$32="","",(($Q$15/$AV$12)/2500)*17) -> 0 | GI25: UV: | GM25: =IF($E$25="","",$E$25) | GW25: =IF($O$25="","",$O$25) | HK25: Karton: | HO25: =IF($O$32="","",(($X$15/$AV$12)/2500)*17) -> 0
A26: Plastika: | AL26: Plastika: | AP26: =IF($E$26="","",$E$26) | AZ26: =IF($O$26="","",$O$26) | BW26: Plastika: | CA26: =IF($E$26="","",$E$26) | CK26: =IF($O$26="","",$O$26) | DI26: Plastika: | DM26: =IF($E$26="","",$E$26) | DW26: =IF($O$26="","",$O$26) | EV26: Plastika: | EZ26: =IF($E$26="","",$E$26) | FJ26: =IF($O$26="","",$O$26) | GI26: Plastika: | GM26: =IF($E$26="","",$E$26) | GW26: =IF($O$26="","",$O$26)
AC27: Vsota: | AG27: =SUM(AG24:AJ25) -> 51.291429 | BN27: Vsota: | BR27: =SUM(BR24:BU25) -> 0 | CY27: Vsota: | DC27: =SUM(DC24:DF25) -> 0 | EK27: Vsota: | EO27: =SUM(EO24:ER25) -> 0 | FX27: Vsota: | GB27: =SUM(GB24:GE25) -> 0 | HK27: Vsota: | HO27: =SUM(HO24:HR25) -> 0
Q28: Vsota: | U28: =SUM(U23:Z26) -> 559.44 | BB28: Vsota: | BF28: =SUM(BF23:BK26) -> 0 | CM28: Vsota: | CQ28: =SUM(CQ23:CV26) -> 0 | DY28: Vsota: | EC28: =SUM(EC23:EH26) -> 0 | FL28: Vsota: | FP28: =SUM(FP23:FU26) -> 0 | GY28: Vsota: | HC28: =SUM(HC23:HH26) -> 0
A30: MATERIAL Ovitek: | L30: =E32 -> incada 250g | AL30: MATERIAL Ovitek: | AW30: =AP32 -> incada 250g | BW30: MATERIAL Ovitek: | CH30: =CA32 -> incada 250g | DI30: MATERIAL Ovitek: | DT30: =DM32 -> incada 250g | EV30: MATERIAL Ovitek: | FG30: =EZ32 -> incada 250g | GI30: MATERIAL Ovitek: | GT30: =GM32 -> incada 250g
A32: Karton: | E32: incada 250g | O32: 0.123 | T32: 2 | U32: =IF($T$32="","",IF($T$32=1,($DL$11*$J$11*$O$32)/$AV$12*1.05,IF($T$32=2,($J$11/2*$DL$12*$O$32)/$AV$12*1.05,IF($T$32=3,($J$11*$O$32*$DL$13)/$AV$12*1.05)))) -> 0 | AL32: Karton: | AP32: =IF($E$32="","",$E$32) -> incada 250g | AZ32: =IF($O$32="","",$O$32) -> 0.123 | BE32: =IF($T$32="","",$T$32) -> 2 | BF32: =IF($BE$32="","",IF($BE$32=1,($DL$11*$Q$11*$O$32)/$AV$12*1.05,IF($BE$32=2,($Q$11/2*$DL$12*$O$32)/$AV$12*1.05,IF($BE$32=3,($Q$11*$O$32*$DL$13)/$AV$12*1.05)))) -> 0 | BW32: Karton: | CA32: =IF($E$32="","",$E$32) -> incada 250g | CK32: =IF($O$32="","",$O$32) -> 0.123 | CP32: =IF($T$32="","",$T$32) -> 2 | CQ32: =IF($CP$32="","",IF($CP$32=1,($DL$11*$X$11*$O$32)/$AV$12*1.05,IF($CP$32=2,($X$11/2*$DL$12*$O$32)/$AV$12*1.05,IF($CP$32=3,($X$11*$O$32*$DL$13)/$AV$12*1.05)))) -> 0 | DI32: Karton: | DM32: =IF($E$32="","",$E$32) -> incada 250g | DW32: =IF($O$32="","",$O$32) -> 0.123 | EB32: =IF($T$32="","",$T$32) -> 2 | EC32: =IF($T$32="","",IF($T$32=1,($DL$11*$J$15*$O$32)/$AV$12*1.05,IF($T$32=2,($J$15/2*$DL$12*$O$32)/$AV$12*1.05,IF($T$32=3,($J$15*$O$32*$DL$13)/$AV$12*1.05)))) -> 0 | EV32: Karton: | EZ32: =IF($E$32="","",$E$32) -> incada 250g | FJ32: =IF($O$32="","",$O$32) -> 0.123 | FO32: =IF($T$32="","",$T$32) -> 2 | FP32: =IF($BE$32="","",IF($BE$32=1,($DL$11*$Q$15*$O$32)/$AV$12*1.05,IF($BE$32=2,($Q$15/2*$DL$12*$O$32)/$AV$12*1.05,IF($BE$32=3,($Q$15*$O$32*$DL$13)/$AV$12*1.05)))) -> 0 | GI32: Karton: | GM32: =IF($E$32="","",$E$32) -> incada 250g | GW32: =IF($O$32="","",$O$32) -> 0.123 | HB32: =IF($T$32="","",$T$32) -> 2 | HC32: =IF($CP$32="","",IF($CP$32=1,($DL$11*$X$15*$O$32)/$AV$12*1.05,IF($CP$32=2,($X$15/2*$DL$12*$O$32)/$AV$12*1.05,IF($CP$32=3,($X$15*$O$32*$DL$13)/$AV$12*1.05)))) -> 0
A33: Folija: | AL33: Folija: | AP33: =IF($E$33="","",$E$33) | AZ33: =IF($O$33="","",$O$33) | BW33: Folija: | CA33: =IF($E$33="","",$E$33) | CK33: =IF($O$33="","",$O$33) | DI33: Folija: | DM33: =IF($E$33="","",$E$33) | DW33: =IF($O$33="","",$O$33) | EV33: Folija: | EZ33: =IF($E$33="","",$E$33) | FJ33: =IF($O$33="","",$O$33) | GI33: Folija: | GM33: =IF($E$33="","",$E$33) | GW33: =IF($O$33="","",$O$33)
A34: UV: | AL34: UV: | AP34: =IF($E$34="","",$E$34) | AZ34: =IF($O$34="","",$O$34) | BW34: UV: | CA34: =IF($E$34="","",$E$34) | CK34: =IF($O$34="","",$O$34) | DI34: UV: | DM34: =IF($E$34="","",$E$34) | DW34: =IF($O$34="","",$O$34) | EV34: UV: | EZ34: =IF($E$34="","",$E$34) | FJ34: =IF($O$34="","",$O$34) | GI34: UV: | GM34: =IF($E$34="","",$E$34) | GW34: =IF($O$34="","",$O$34)
A35: Plastika: | AL35: Plastika: | AP35: =IF($E$35="","",$E$35) | AZ35: =IF($O$35="","",$O$35) | BW35: Plastika: | CA35: =IF($E$35="","",$E$35) | CK35: =IF($O$35="","",$O$35) | DI35: Plastika: | DM35: =IF($E$35="","",$E$35) | DW35: =IF($O$35="","",$O$35) | EV35: Plastika: | EZ35: =IF($E$35="","",$E$35) | FJ35: =IF($O$35="","",$O$35) | GI35: Plastika: | GM35: =IF($E$35="","",$E$35) | GW35: =IF($O$35="","",$O$35)
P37: Vsota: | T37: =SUM(U32:Y34) -> 0 | BA37: Vsota: | BE37: =SUM(BF32:BJ34) -> 0 | CL37: Vsota: | CP37: =SUM(CQ32:CU35) -> 0 | DX37: Vsota: | EB37: =SUM(EC32:EG35) -> 0 | FK37: Vsota: | FO37: =SUM(FP32:FT35) -> 0 | GX37: Vsota: | HB37: =SUM(HC32:HG35) -> 0
A39: PRIPRAVA TF: | AL39: PRIPRAVA TF: | BW39: PRIPRAVA TF: | DI39: PRIPRAVA TF: | EV39: PRIPRAVA TF: | GI39: PRIPRAVA TF:
A40: Plošče: | E40: 8 | H40: =IF($E$40="","",$E$40*6) -> 48 | AL40: Plošče: | AP40: =IF($E$40="","",$E$40) -> 8 | AS40: =IF($H$40="","",$H$40) -> 48 | BW40: Plošče: | CA40: =IF($E$40="","",$E$40) -> 8 | CD40: =IF($H$40="","",$H$40) -> 48 | DI40: Plošče: | DM40: =IF($E$40="","",$E$40) -> 8 | DP40: =IF($H$40="","",$H$40) -> 48 | EV40: Plošče: | EZ40: =IF($E$40="","",$E$40) -> 8 | FC40: =IF($H$40="","",$H$40) -> 48 | GI40: Plošče: | GM40: =IF($E$40="","",$E$40) -> 8 | GP40: =IF($H$40="","",$H$40) -> 48
A41: Repro: | E41: 1 | H41: =IF($E$41="","",$E$41*21) -> 21 | AL41: Repro: | AP41: =IF($E$41="","",$E$41) -> 1 | AS41: =IF($H$41="","",$H$41) -> 21 | BW41: Repro: | CA41: =IF($E$41="","",$E$41) -> 1 | CD41: =IF($H$41="","",$H$41) -> 21 | DI41: Repro: | DM41: =IF($E$41="","",$E$41) -> 1 | DP41: =IF($H$41="","",$H$41) -> 21 | EV41: Repro: | EZ41: =IF($E$41="","",$E$41) -> 1 | FC41: =IF($H$41="","",$H$41) -> 21 | GI41: Repro: | GM41: =IF($E$41="","",$E$41) -> 1 | GP41: =IF($H$41="","",$H$41) -> 21
D43: Vsota: | H43: =SUM(H40:L41) -> 69 | AO43: Vsota: | AS43: =SUM(AS40:AW41) -> 69 | BZ43: Vsota: | CD43: =SUM(CD40:CH41) -> 69 | DL43: Vsota: | DP43: =SUM(DP40:DT41) -> 69 | EY43: Vsota: | FC43: =SUM(FC40:FG41) -> 69 | GL43: Vsota: | GP43: =SUM(GP40:GT41) -> 69
A45: TISK: | AL45: TISK: | BW45: TISK: | DI45: TISK: | EV45: TISK: | GI45: TISK:
A46: H5 - R300: | G46: Vložek: | P46: H5 - R300: | V46: Ovitek: | AL46: H5 - R300: | AR46: Vložek: | BA46: H5 - R300: | BG46: Ovitek: | BW46: H5 - R300: | CC46: Vložek: | CL46: H5 - R300: | CR46: Ovitek: | DI46: H5 - R300: | DO46: Vložek: | DX46: H5 - R300: | ED46: Ovitek: | EV46: H5 - R300: | FB46: Vložek: | FK46: H5 - R300: | FQ46: Ovitek: | GI46: H5 - R300: | GO46: Vložek: | GX46: H5 - R300: | HD46: Ovitek:
A47: Priprava: | F47: 2 | J47: =IF(F47="","",F47*67) -> 134 | P47: Priprava: | U47: 0.5 | Y47: =IF(U47="","",U47*67) -> 33.5 | AL47: Priprava: | AQ47: =IF($F$47="","",$F$47) -> 2 | AU47: =IF(AQ47="","",AQ47*67) -> 134 | BA47: Priprava: | BF47: =IF($U$47="","",$U$47) -> 0.5 | BJ47: =IF(BF47="","",BF47*67) -> 33.5 | BW47: Priprava: | CB47: =IF($F$47="","",$F$47) -> 2 | CF47: =IF(CB47="","",CB47*67) -> 134 | CL47: Priprava: | CQ47: =IF($U$47="","",$U$47) -> 0.5 | CU47: =IF(CQ47="","",CQ47*67) -> 33.5 | DI47: Priprava: | DN47: =IF($F$47="","",$F$47) -> 2 | DR47: =IF(DN47="","",DN47*67) -> 134 | DX47: Priprava: | EC47: =IF($U$47="","",$U$47) -> 0.5 | EG47: =IF(EC47="","",EC47*67) -> 33.5 | EV47: Priprava: | FA47: =IF($F$47="","",$F$47) -> 2 | FE47: =IF(FA47="","",FA47*67) -> 134 | FK47: Priprava: | FP47: =IF($U$47="","",$U$47) -> 0.5 | FT47: =IF(FP47="","",FP47*67) -> 33.5 | GI47: Priprava: | GN47: =IF($F$47="","",$F$47) -> 2 | GR47: =IF(GN47="","",GN47*67) -> 134 | GX47: Priprava: | HC47: =IF($U$47="","",$U$47) -> 0.5 | HG47: =IF(HC47="","",HC47*67) -> 33.5
A48: Tisk: | F48: 5 | J48: =IF(F48="","",F48*67) -> 335 | P48: Tisk: | U48: 0.5 | Y48: =IF(U48="","",U48*67) -> 33.5 | AL48: Tisk: | AQ48: =IF($Q$11="","",(($Q$11*$DL$1*2+$Q$11*($DL$2/2)*2+$DL$8*$Q$11))/4000+0.25) | AU48: =IF(AQ48="","",AQ48*67) | BA48: Tisk: | BF48: =IF($Q$11="","",(($Q$11*$DL$11*2+$Q$11*($DL$12/2)*2+$Q$11*$DL$13))/4000+0.25) | BJ48: =IF(BF48="","",BF48*67) | BW48: Tisk: | CB48: =IF($X$11="","",(($X$11*$DL$1*2+$X$11*($DL$2/2)*2+$DL$8*$X$11))/4000+0.25) | CF48: =IF(CB48="","",CB48*67) | CL48: Tisk: | CQ48: =IF($X$11="","",(($X$11*$DL$11*2+$X$11*($DL$12/2)*2+$X$11*$DL$13))/4000+0.25) | CU48: =IF(CQ48="","",CQ48*67) | DI48: Tisk: | DN48: =IF($J$15="","",(($J$15*$DL$1*2+$J$15*($DL$2/2)*2+$J$15*$DL$8))/4000+0.25) | DR48: =IF(DN48="","",DN48*67) | DX48: Tisk: | EC48: =IF($Q$11="","",(($J$11*$DL$11*2+$J$11*($DL$12/2)*2+$J$11*$DL$13))/4000+0.25) | EG48: =IF(EC48="","",EC48*67) | EV48: Tisk: | FA48: =IF($Q$15="","",(($Q$15*$DL$1*2+$Q$15*($DL$2/2)*2+$DL$8*$Q$15))/4000+0.25) | FE48: =IF(FA48="","",FA48*67) | FK48: Tisk: | FP48: =IF($Q$11="","",(($Q$11*$DL$11*2+$Q$11*($DL$12/2)*2+$Q$11*$DL$13))/4000+0.25) | FT48: =IF(FP48="","",FP48*67) | GI48: Tisk: | GN48: =IF($X$15="","",(($X$15*$DL$1*2+$X$15*($DL$2/2)*2+$DL$8*$X$15))/4000+0.25) | GR48: =IF(GN48="","",GN48*67) | GX48: Tisk: | HC48: =IF($X$15="","",(($X$15*$DL$11*2+$X$15*($DL$12/2)*2+$X$15*$DL$13))/4000+0.25) | HG48: =IF(HC48="","",HC48*67)
A50: Disp. LAK: | G50: Vložek: | P50: Disp. LAK: | V50: Ovitek: | AL50: Disp. LAK: | AR50: Vložek: | BA50: Disp. LAK: | BG50: Ovitek: | BW50: Disp. LAK: | CL50: Disp. LAK: | CR50: Ovitek: | DI50: Disp. LAK: | DX50: Disp. LAK: | ED50: Ovitek: | EV50: Disp. LAK: | FK50: Disp. LAK: | FQ50: Ovitek: | GI50: Disp. LAK: | GX50: Disp. LAK: | HD50: Ovitek:
...

Sheet LETAKI DOPISI
A1: PONUDBA ZA LETAKE / DOPISE | CS1: IZ B1 = TP | CX1: 700x500 | DD1: 2
CS2: IZ B1 = TP | CX2: 700x330 | DD2: 3
A3: NAROČNIK: | AV3: KOMERCIALIST: | BE3: Rok Kadilnik | CS3: IZ B1 = TP | CX3: 500x350 | DD3: 4
A4: PONUDBA ZA: | CS4: IZ B1 = TP | CX4: 350x250 | DD4: 8
A5: FAZE DELA:
CS6: DOPISI - LETAKI A/B | DE6: 1
A7: TISK: | CS7: DOPISI - LETAKI A/Obr.:
A8: DODELAVA: | AV8: Papir: | AZ8: Iz B1 pole: | BH8: x | BI8: Format TP: | BN8: =IF(BF8="","",IF(BF8=2,$CX$1,IF(BF8=3,$CX$2,IF(BF8=4,$CX$3,IF(BF8=8,$CX$4))))) | CS8: DOPISI - LETAKI A/0
AV9: Karton: | AZ9: Iz B1 pole: | BF9: 2 | BH9: x | BI9: Format TP: | BN9: =IF(BF9="","",IF(BF9=2,$CX$1,IF(BF9=3,$CX$2,IF(BF9=4,$CX$3,IF(BF9=8,$CX$4))))) -> 700x500
A10: Št. TP: | H10: Papir: | L10: =IF($BF$8="","",J12/$AZ$12) | S10: =IF($BF$8="","",Q12/$AZ$12) | Z10: =IF($BF$8="","",X12/$AZ$12) | AG10: =IF($BF$8="","",AE12/$AZ$12) | AN10: =IF($BF$8="","",AL12/$AZ$12)
H11: Karton: | L11: =IF($BF$9="",0,ROUNDUP((J12/$AZ$13)/$BF$9,)*1) -> 125 | S11: =IF($BF$9="",0,ROUNDUP((Q12/$AZ$13)/$BF$9,)*1) -> 625 | Z11: =IF($BF$9="",0,ROUNDUP((X12/$AZ$13)/$BF$9,)*1) -> 1250 | AG11: =IF($BF$9="",0,ROUNDUP((AE12/$AZ$13)/$BF$9,)*1) -> 2500 | AN11: =IF($BF$9="",0,ROUNDUP((AL12/$AZ$13)/$BF$9,)*1) -> 6250
A12: NAKLADA: | J12: 1000 | Q12: 5000 | X12: 10000 | AE12: 20000 | AL12: 50000 | AV12: Na TP: | BC12: Na B1: | BG12: =IF(AZ12="","",AZ12*BF8)
A13: CENA: | J13: =IF(J12="","",IF(BC24=J12,BL86)) -> FALSE | Q13: =IF(Q12="","",IF(BL24=Q12,BU86)) -> FALSE | X13: =IF(X12="","",IF(BU24=X12,CD86)) -> FALSE | AE13: =IF(AE12="","",IF(CD24=AE12,CM86)) -> FALSE | AL13: =IF(AL12="","",IF(CM24=AL12,CV86)) -> FALSE | AV13: Na TP: | AZ13: 4 | BC13: Na B1: | BG13: =IF(AZ13="","",AZ13*BF9) -> 8
A14: CENA ZA KOS: | J14: =IF(J13="","",IF(#REF!=J13,BL87)) -> #REF! | Q14: =IF(Q13="","",IF(BL25=Q13,BU87)) -> 0 | X14: =IF(X13="","",IF(BU25=X13,CD87)) -> 0 | AE14: =IF(AE13="","",IF(CD25=AE13,CM87)) -> 0 | AL14: =IF(AL13="","",IF(CM25=AL13,CV87)) -> 0
A17: MATERIAL : | AE17: RAZREZ Papirja:
A18: Papir: | E18: Offset 90g BB | V18: =IF(Q18="","",$Q$18*$L$10/$BF$8) | AE18: Papir: | AJ18: =IF(BF8="","",((L10/BF8)*17)/3500)
A19: Karton: | E19: Burgo gloss 250g SB | Q19: 0.21 | V19: =IF(Q19="","",$Q$19*$L$11/$BF$9) -> 13.125 | AE19: Karton: | AJ19: =IF(BF9="","",((L11/BF9)*17)/2500) -> 0.425
A20: Folija:
A21: UV:
Q23: VSOTA: | V23: =SUM(V18:Z21) -> 13.125 | AE23: VSOTA: | AJ23: =SUM(AJ18:AM19) -> 0.425
A26: IZDELAVA TISKOVNE FORME:
A27: Plošče: | E27: 4 | I27: =IF(E27="","",$E$27*6) -> 24
A28: Repro: | E28: =IF(E27="","",1) -> 1 | I28: =IF(E28="","",21) -> 21
C30: VSOTA: | H30: =IF(I27="","",I27+I28) -> 45
A32: TISK:
A33: H5
A34: Priprava: | E34: 1 | I34: =IF(E34="","",E34*67) -> 67
A35: Tisk: | E35: =IF(E34="","",IF(DE6=1,((L11+L10)*2)/4000,IF(DE7=1,((L11+L10)*2)/4000,IF(DE8=1,(L11+L10)/4000)))) -> #VALUE! | I35: =IF(E35="","",E35*67) -> #VALUE!
A37: DISPERZIJSKI LAK | K37: 1
A38: Priprava: | E38: =IF(K37="","",0.5) -> 0.5 | I38: =IF(E38="","",E38*60) -> 30
A39: Tisk: | E39: =IF(K37="","",IF(K37=1,L10+L11,IF(K37=2,L11+L10*2))) -> #VALUE! | I39: =IF(E39="","",E39*0.1) -> #VALUE!
A41: PM
A42: Priprava:
A43: Tisk:

Sheet CENA MATERIALA
E1: IZRAČUN CENE MATERALA
A3: DIMENZIJA POLE | E3: gramatura | F3: površina | G3: tona/1000 kg | H3: cena pole+5% | I3: število pol v toni | J3: ŽELJENA KOLIČINA POL | K3: CENA ZA KOLIČINO | L3: TEŽA SKUPAJ - TON
A4: 1020 | B4: x | C4: 710 | E4: 90 | F4: =IF(A4="","",(A4*C4)/1000000) -> 0.7242 | G4: 1500 | H4: =IF(E4="","", ((E4*F4*G4)/1000000)*1.05) -> 0.10265535 | I4: =IF(E4="","",1000000/(E4*F4)) -> 15342.6 | K4: =IF(H4="","",H4*J4) -> 0 | L4: =IF(J4="","",J4/I4)

Sheet PONUDBA (2)
E1: KALKULACIJA št.: | H1: 1
P2: Datum: | R2: =NOW() -> 45614.789
A3: NAROČNIK: | L3: KOMERCIALIST: | Q3: Tilen Petrič
A4: PONUDBA ZA:
A7: FAZE DELA: | E7: TISK: | F7: Zloženke 230467N Glyphomax 8 strani 4/1
E8: DODELAVA: | F8: razrez+izsek+zgibanje
E12: IZ B1 POLE: | H12: 4 | J12: Format TP: | M12: 500 | N12: x | O12: 350 | Q12: NA TISK. POLI: | U12: 2
A14: NAKLADA: | G14: 4550 | I14: 8000 | M14: 8000
A15: CENA: | G15: =IF(H35="","",IF(H35=G14,R86)) -> 339.47528 | I15: =IF(I14="","",AP86) -> 478.54673 | M15: =IF(M14="","",BK86) -> 478.54673 | R15: Cena materiala/TONA | Z15: ='CENA MATERIALA'!G5 -> 0 | AB15: ='CENA MATERIALA'!G4 -> 1500
A16: CENA ZA KOS: | G16: =IF(G15="","",G15/G14) -> 0.074609952 | I16: =IF(I15="","",I15/I14) -> 0.059818341 | M16: =IF(M15="","",M15/M14) -> 0.059818341
A17: CENA / 1.000: | G17: =IF(G14="","",G16*1000) -> 74.609952 | I17: =IF(I14="","",I16*1000) -> 59.818341 | M17: =IF(M14="","",M16*1000) -> 59.818341 | R17: Cena materiala/POLA | AB17: ='CENA MATERIALA'!H4 -> 0.10265535
E18: Št.TISK. POL: | G18: =IF(H12="","",(ROUNDUP(G14/U12,0))) -> 2275 | J18: =IF(H12="","",ROUNDUP(I14/U12,0)) -> 4000 | M18: =M14/U12 -> 4000
E19: DODATEK | G19: 225 | J19: 300 | M19: 300
E20: Št. TISK.POL | G20: =IF(G18="","",G18+G19) -> 2500 | J20: =IF(J18="","",J18+J19) -> 4300 | M20: =IF(M18="","",M18+M19) -> 4300
E21: POL / RAZREZ: | G21: =IF($H$12="","",(ROUNDUP(G20/$H$12,0))) -> 625 | J21: =IF($H$12="","",(ROUNDUP(J20/$H$12,0))) -> 1075 | M21: =IF($H$12="","",(ROUNDUP(M20/$H$12,0))) -> 1075
A24: NAKLADA: | G24: 1000 | I24: 1000 | M24: 1000 | P24: ORODJE | R24: =IF(O52="","",IF(O52>0,200)) | S24: =IF(O46="","",IF(O46=1,"",IF(O46=2,"",IF(O46=3,"",IF(O46=4,"",IF(O46=5,200))))))
A25: CENA: | G25: =IF(G24="","",CG86) -> 215.82713 | I25: =IF(I24="","",DC86) -> 215.82713 | M25: =IF(M24="","",DY86) -> 215.82713
A26: CENA ZA KOS: | G26: =IF(G25="","",G25/G24) -> 0.21582713 | I26: =IF(I25="","",I25/I24) -> 0.21582713 | M26: =IF(M25="","",M25/M24) -> 0.21582713
A27: CENA / 1.000: | G27: =IF(G24="","",G26*1000) -> 215.82713 | I27: =IF(I24="","",I26*1000) -> 215.82713 | M27: =IF(M24="","",M26*1000) -> 215.82713
E29: Št.TISK. POL: | G29: =G24/U12 -> 500 | J29: =I24/U12 -> 500 | M29: =M24/U12 -> 500 | P29: KLIŠE | R29: =IF(P29="","",KLIŠE!H11)
E30: Z DODATKOM: | G30: 300 | J30: 300 | M30: 300
E31: Št. TISK.POL | G31: =IF(G29="","",G29+G30) -> 800 | J31: =IF(J29="","",J29+J30) -> 800 | M31: =IF(M29="","",M29+M30) -> 800 | P31: =IF(B37="","",B37)
E32: POL / RAZREZ: | G32: =IF($H$12="","",(ROUNDUP(G31/$H$12,0))) -> 200 | J32: =IF($H$12="","",(ROUNDUP(J31/$H$12,0))) -> 200 | M32: =IF($H$12="","",(ROUNDUP(M31/$H$12,0))) -> 200 | P32: =IF(B40="","",B40)
A35: MATERIAL: | H35: =IF(G14="","",G14) -> 4550 | K35: RAZREZ PAPIRJA: | Z35: MATERIAL: | AG35: =IF(I14="","",I14) -> 8000 | AJ35: RAZREZ PAPIRJA: | AU35: MATERIAL: | BB35: =IF(M14="","",M14) -> 8000 | BE35: RAZREZ PAPIRJA: | BP35: MATERIAL: | BW35: =IF(G24="","",G24) -> 1000 | BZ35: RAZREZ PAPIRJA: | CL35: MATERIAL: | CS35: =IF(I24="","",I24) -> 1000 | CV35: RAZREZ PAPIRJA: | DH35: MATERIAL: | DO35: =IF(M24="","",M24) -> 1000 | DR35: RAZREZ PAPIRJA:
B36: Papir: | L36: Razrez 1: | O36: 1 | P36: =IF(O36="","",IF(($H$35/($H$12)/2500)<=0.5,0.25,IF(($H$35/($H$12)/2500)>0.25,($H$35/($H$12)/2500)))) -> 0.25 | R36: =IF(P36="","",(P36*17)) -> 4.25 | AA36: Papir: | AK36: Razrez 1: | AM36: =IF($O$36="","",$O$36) -> 1 | AN36: =IF(AM36="","",IF(($AG$35/($H$12)/2500)<=0.5,0.5,IF(($AG$35/($H$12)/2500)>0.25,($AG$35/($H$12)/2500)))) -> 0.8 | AP36: =IF(AN36="","",(AN36*17)) -> 13.6 | AV36: Papir: | BF36: Razrez 1: | BH36: =IF($O$36="","",$O$36) -> 1 | BI36: =IF(BH36="","",IF(($BB$35/($H$12)/2500)<=0.25,0.5,IF(($BB$35/($H$12)/2500)>0.5,($BB$35/($H$12)/2500)))) -> 0.8 | BK36: =IF(BI36="","",(BI36*17)) -> 13.6 | BQ36: Papir: | CA36: Razrez 1: | CD36: =BH36 -> 1 | CE36: =IF(CD36="","",IF(($BW$35/($H$12)/2500)<=0.5,0.5,IF(($BW$35/($H$12)/2500)>0.25,($BW$35/($H$12)/2500)))) -> 0.5 | CG36: =IF(CE36="","",(CE36*17)) -> 8.5 | CM36: Papir: | CW36: Razrez 1: | CZ36: =CD36 -> 1 | DA36: =IF(CZ36="","",IF(($CS$35/($H$12)/2500)<=0.5,0.5,IF(($CS$35/($H$12)/2500)>0.25,($CS$35/($H$12)/2500)))) -> 0.5 | DC36: =IF(DA36="","",(DA36*17)) -> 8.5 | DI36: Papir: | DS36: Razrez 1: | DV36: =CZ36 -> 1 | DW36: =IF(DV36="","",IF(($DO$35/($H$12)/2500)<=0.5,0.5,IF(($DO$35/($H$12)/2500)>0.25,($DO$35/($H$12)/2500)))) -> 0.5 | DY36: =IF(DW36="","",(DW36*17)) -> 8.5
